Workbook

Sheet README
A1: Dark Filaments — Simulator v1.2.1
A2: Strategy overhaul: greedy value-per-cost replaces balanced-build. Save mode threshold is dynamic based on VPC ratios. No schema changes from v1.2.
A4: The three core stats
A5: • MPC — Mass per Click — affects active click income AND autoclicker output
A6: • MPS — Mass per Second — passive income rate
A7: • APS — Autoclicks per Second — fake clicks per second from autoclickers
A8: Game tick = 1 second. Total income/sec = (cpm/60 × MPC × active) + (APS × MPC) + MPS.
A9: Simulator measures in 10-second chunks (10 game ticks per sim row).
A11: Unified upgrade schema
A12: Every upgrade has the same fields. Most fields will be 0 (additive) or 1.0 (multiplicative) for any given upgrade — only the ones that actually do something get filled in.
A14: Per-stat fields (one set each for M/sec, M/click, AC/sec):
A15: • Base — constant value when level ≥ 1, before any multipliers
... A63: Yellow = editable input. Light green = derived live calculation. Black text = formula. Green text = cross-tab reference.

Sheet Parameters
A1: Parameters
A2: Edit yellow cells. Everything else updates automatically.
A4: Time budget
A5: Total target playtime (minutes) | B5: 595 | C5: Casual pace at 45 cpm. 60 cpm players will finish closer to ~480 min.
A6: Number of tiers | B6: 10 | C6: Solar System through Causal Horizon.
A7: Tier real-time growth rate | B7: 1.3 | C7: Each tier takes this many times as long as the previous one.
A8: Click & income
A9: Base click value (Mass per click, no upgrades) | B9: 1 | C9: The unit of the economy. Each click yields this much Mass with zero upgrades.
A10: Average clicks per minute when active | B10: 100 | C10: Reflects autoclicker / engaged play. Prototype dynamically reports actual cpm.
A11: Active play fraction (0–1) | B11: 1 | C11: Prototype reports cpm in real time, so this stays at 1.0; AFK time is captured by cpm dropping.
A12: Click importance curve (U-shape, diagnostic only)
A13: Click share at Tier 1 | B13: 0.6 | C13: Clicks dominate at start.
A14: Click share minimum (Tier 5 dip) | B14: 0.05 | C14: Crescendo — chain reactions handle nearly everything.
A15: Click share late game (Tier 9) | B15: 0.65 | C15: 'Hanging on.'
A16: Click share endgame (Tier 10) | B16: 0.7 | C16: Click becomes ritual.
A17: Cohesion (gates tier transitions)
A18: Cohesion cost: T1 → T2 transition | B18: 1 | C18: Tutorial-friendly.
A19: Cohesion cost growth per tier | B19: 2.5 | C19: Geometric growth.
A20: Simulator strategy
A21: VPC save threshold | B21: 1.5 | C21: Save mode triggers when next-target VPC > (best-affordable VPC × this). Lower = saves harder.
A22: Offline progression
A23: Offline progression rate (1.0 = full) | B23: 1 | C23: Full offline accumulation; queued events fire on return.
A24: Tier names
A25: Tier 1 name | B25: Solar System | C25: Tutorial.
A26: Tier 2 name | B26: Stellar Neighborhood | C26: First sense of scale. Introduces autoclickers.
A27: Tier 3 name | B27: Galactic Arm
A28: Tier 4 name | B28: Galaxy
A29: Tier 5 name | B29: Local Group | C29: PEAK. Crescendo.
A30: Tier 6 name | B30: Galactic Cluster
A31: Tier 7 name | B31: Supercluster
A32: Tier 8 name | B32: Filament
A33: Tier 9 name | B33: Cosmic Web
A34: Tier 10 name | B34: Causal Horizon | C34: Endgame.

Sheet Upgrades
A1: Upgrades — unified schema
A2: Each row is one upgrade. Yellow cells editable. Most cells will be 0 (additive) or 1.0 (multiplicative) — only the levers that actually do something get filled in. Completionist = missable upgrade. Synergy target/mult lets one upgrade buff another's self-contribution geometrically with level.
A4: Identity | C4: Cost & limits | G4: Self M/sec | J4: Self M/click | M4: Self AC/sec | P4: Global multipliers | S4: Completion | T4: Synergy | V4: Description
A5: Tier | B5: Name | C5: Init cost | D5: Cost growth | E5: Max levels | F5: Cohesion + | G5: Base | H5: + /lvl | I5: × self /lvl | J5: Base | K5: + /lvl | L5: × self /lvl | M5: Base | N5: + /lvl | O5: × self /lvl | P5: × all M/sec /lvl | Q5: × all M/click /lvl | R5: × all AC speed /lvl | S5: Completionist? | T5: Synergy target | U5: Synergy mult/lvl | V5: Description voice
A6: 1 | B6: Solar Wind | C6: 7 | D6: 1.15 | E6: 99 | F6: 0 | G6: 0 | H6: 0.08 | I6: 1 | J6: 0 | K6: 0 | L6: 1 | M6: 0 | N6: 0 | O6: 1 | P6: 1 | Q6: 1 | R6: 1 | S6: 0 | U6: 1 | V6: Charged particles drift outward and return with company. We are pulling more than we used to.
A7: 1 | B7: Asteroid Belt | C7: 20 | D7: 1.15 | E7: 99 | F7: 0 | G7: 0 | H7: 0.2 | I7: 1 | J7: 0 | K7: 0 | L7: 1 | M7: 0 | N7: 0 | O7: 1 | P7: 1 | Q7: 1 | R7: 1 | S7: 0 | U7: 1 | V7: The belt yields. Iron, ice, the slow gravel of the early system. Each rock finds us.
A8: 1 | B8: Stellar Coupling | C8: 22 | D8: 1.4 | E8: 99 | F8: 0 | G8: 0 | H8: 0 | I8: 1 | J8: 0 | K8: 0.35 | L8: 1 | M8: 0 | N8: 0 | O8: 1 | P8: 1 | Q8: 1 | R8: 1 | S8: 0 | U8: 1 | V8: We pull harder. The center holds tighter.
A9: 1 | B9: Magnetosphere | C9: 80 | D9: 2 | E9: 5 | F9: 0 | G9: 0 | H9: 1 | I9: 1 | J9: 0 | K9: 0 | L9: 1 | M9: 0 | N9: 0 | O9: 1 | P9: 1 | Q9: 1 | R9: 1 | S9: 1 | U9: 1 | V9: The system's invisible shell. Charged particles arc and return. We catch what would have escaped.
A10: 1 | B10: Orbital Resonance | C10: 240 | D10: 1 | E10: 1 | F10: 0.4 | G10: 0 | H10: 0 | I10: 1 | J10: 0 | K10: 0 | L10: 1 | M10: 0 | N10: 0 | O10: 1 | P10: 1.25 | Q10: 1 | R10: 1 | S10: 0 | U10: 1 | V10: Periods align. The system breathes in time with us. Everything we touch becomes synchronous.
A11: 1 | B11: Heliopause | C11: 575 | D11: 1 | E11: 1 | F11: 0.6 | G11: 0 | H11: 0 | I11: 1 | J11: 0 | K11: 0 | L11: 1 | M11: 0 | N11: 0 | O11: 1 | P11: 1 | Q11: 1 | R11: 1 | S11: 0 | T11: Stellar Coupling | U11: 1.5 | V11: We have reached the edge of our influence. Beyond it, the rest of the galaxy waits.
A12: 1 | B12: First Photons | C12: 850 | D12: 1 | E12: 1 | F12: 0 | G12: 1 | H12: 0 | I12: 1 | J12: 0 | K12: 0 | L12: 1 | M12: 0 | N12: 0 | O12: 1 | P12: 1 | Q12: 1.2 | R12: 1 | S12: 1 | U12: 1 | V12: Light, finally. The first photons leave the surface and find us. Everything quickens.

Sheet TimeBudget
A1: Time budget per tier
A2: Time targets and click share targets per tier. Derived from Parameters.
A4: Tier | B4: Name | C4: Min/tier | D4: Cum min | E4: Click % | F4: Cohesion cost | G4: Notes
A5: 1 | B5: =Parameters!$B$25 -> Solar System | C5: =Parameters!$B$5*POWER(Parameters!$B$7,A5-1)/IF(Parameters!$B$7=1,Parameters!$B$6,(POWER(Parameters!$B$7,Parameters!$B$6)-1)/(Parameters!$B$7-1)) -> 13.960747 | D5: =SUM(C$5:C5) -> 13.960747 | E5: =IF(A5<=5,Parameters!$B$13+(Parameters!$B$14-Parameters!$B$13)*POWER((A5-1)/4,2),IF(A5<=9,Parameters!$B$14+(Parameters!$B$15-Parameters!$B$14)*POWER((A5-5)/4,2),Parameters!$B$16)) -> 0.6 | F5: =IF(A5<Parameters!$B$6,Parameters!$B$18*POWER(Parameters!$B$19,A5-1),0) -> 1 | G5: Tutorial.
A6: 2 | B6: =Parameters!$B$26 -> Stellar Neighborhood | C6: =Parameters!$B$5*POWER(Parameters!$B$7,A6-1)/IF(Parameters!$B$7=1,Parameters!$B$6,(POWER(Parameters!$B$7,Parameters!$B$6)-1)/(Parameters!$B$7-1)) -> 18.148971 | D6: =SUM(C$5:C6) -> 32.109717 | E6: =IF(A6<=5,Parameters!$B$13+(Parameters!$B$14-Parameters!$B$13)*POWER((A6-1)/4,2),IF(A6<=9,Parameters!$B$14+(Parameters!$B$15-Parameters!$B$14)*POWER((A6-5)/4,2),Parameters!$B$16)) -> 0.565625 | F6: =IF(A6<Parameters!$B$6,Parameters!$B$18*POWER(Parameters!$B$19,A6-1),0) -> 2.5 | G6: Autoclickers introduced.
A7: 3 | B7: =Parameters!$B$27 -> Galactic Arm | C7: =Parameters!$B$5*POWER(Parameters!$B$7,A7-1)/IF(Parameters!$B$7=1,Parameters!$B$6,(POWER(Parameters!$B$7,Parameters!$B$6)-1)/(Parameters!$B$7-1)) -> 23.593662 | D7: =SUM(C$5:C7) -> 55.703379 | E7: =IF(A7<=5,Parameters!$B$13+(Parameters!$B$14-Parameters!$B$13)*POWER((A7-1)/4,2),IF(A7<=9,Parameters!$B$14+(Parameters!$B$15-Parameters!$B$14)*POWER((A7-5)/4,2),Parameters!$B$16)) -> 0.4625 | F7: =IF(A7<Parameters!$B$6,Parameters!$B$18*POWER(Parameters!$B$19,A7-1),0) -> 6.25
A8: 4 | B8: =Parameters!$B$28 -> Galaxy | C8: =Parameters!$B$5*POWER(Parameters!$B$7,A8-1)/IF(Parameters!$B$7=1,Parameters!$B$6,(POWER(Parameters!$B$7,Parameters!$B$6)-1)/(Parameters!$B$7-1)) -> 30.67176 | D8: =SUM(C$5:C8) -> 86.375139 | E8: =IF(A8<=5,Parameters!$B$13+(Parameters!$B$14-Parameters!$B$13)*POWER((A8-1)/4,2),IF(A8<=9,Parameters!$B$14+(Parameters!$B$15-Parameters!$B$14)*POWER((A8-5)/4,2),Parameters!$B$16)) -> 0.290625 | F8: =IF(A8<Parameters!$B$6,Parameters!$B$18*POWER(Parameters!$B$19,A8-1),0) -> 15.625
A9: 5 | B9: =Parameters!$B$29 -> Local Group | C9: =Parameters!$B$5*POWER(Parameters!$B$7,A9-1)/IF(Parameters!$B$7=1,Parameters!$B$6,(POWER(Parameters!$B$7,Parameters!$B$6)-1)/(Parameters!$B$7-1)) -> 39.873288 | D9: =SUM(C$5:C9) -> 126.24843 | E9: =IF(A9<=5,Parameters!$B$13+(Parameters!$B$14-Parameters!$B$13)*POWER((A9-1)/4,2),IF(A9<=9,Parameters!$B$14+(Parameters!$B$15-Parameters!$B$14)*POWER((A9-5)/4,2),Parameters!$B$16)) -> 0.05 | F9: =IF(A9<Parameters!$B$6,Parameters!$B$18*POWER(Parameters!$B$19,A9-1),0) -> 39.0625 | G9: PEAK.
A10: 6 | B10: =Parameters!$B$30 -> Galactic Cluster | C10: =Parameters!$B$5*POWER(Parameters!$B$7,A10-1)/IF(Parameters!$B$7=1,Parameters!$B$6,(POWER(Parameters!$B$7,Parameters!$B$6)-1)/(Parameters!$B$7-1)) -> 51.835275 | D10: =SUM(C$5:C10) -> 178.0837 | E10: =IF(A10<=5,Parameters!$B$13+(Parameters!$B$14-Parameters!$B$13)*POWER((A10-1)/4,2),IF(A10<=9,Parameters!$B$14+(Parameters!$B$15-Parameters!$B$14)*POWER((A10-5)/4,2),Parameters!$B$16)) -> 0.0875 | F10: =IF(A10<Parameters!$B$6,Parameters!$B$18*POWER(Parameters!$B$19,A10-1),0) -> 97.65625
A11: 7 | B11: =Parameters!$B$31 -> Supercluster | C11: =Parameters!$B$5*POWER(Parameters!$B$7,A11-1)/IF(Parameters!$B$7=1,Parameters!$B$6,(POWER(Parameters!$B$7,Parameters!$B$6)-1)/(Parameters!$B$7-1)) -> 67.385857 | D11: =SUM(C$5:C11) -> 245.46956 | E11: =IF(A11<=5,Parameters!$B$13+(Parameters!$B$14-Parameters!$B$13)*POWER((A11-1)/4,2),IF(A11<=9,Parameters!$B$14+(Parameters!$B$15-Parameters!$B$14)*POWER((A11-5)/4,2),Parameters!$B$16)) -> 0.2 | F11: =IF(A11<Parameters!$B$6,Parameters!$B$18*POWER(Parameters!$B$19,A11-1),0) -> 244.14062
A12: 8 | B12: =Parameters!$B$32 -> Filament | C12: =Parameters!$B$5*POWER(Parameters!$B$7,A12-1)/IF(Parameters!$B$7=1,Parameters!$B$6,(POWER(Parameters!$B$7,Parameters!$B$6)-1)/(Parameters!$B$7-1)) -> 87.601614 | D12: =SUM(C$5:C12) -> 333.07117 | E12: =IF(A12<=5,Parameters!$B$13+(Parameters!$B$14-Parameters!$B$13)*POWER((A12-1)/4,2),IF(A12<=9,Parameters!$B$14+(Parameters!$B$15-Parameters!$B$14)*POWER((A12-5)/4,2),Parameters!$B$16)) -> 0.3875 | F12: =IF(A12<Parameters!$B$6,Parameters!$B$18*POWER(Parameters!$B$19,A12-1),0) -> 610.35156
A13: 9 | B13: =Parameters!$B$33 -> Cosmic Web | C13: =Parameters!$B$5*POWER(Parameters!$B$7,A13-1)/IF(Parameters!$B$7=1,Parameters!$B$6,(POWER(Parameters!$B$7,Parameters!$B$6)-1)/(Parameters!$B$7-1)) -> 113.8821 | D13: =SUM(C$5:C13) -> 446.95327 | E13: =IF(A13<=5,Parameters!$B$13+(Parameters!$B$14-Parameters!$B$13)*POWER((A13-1)/4,2),IF(A13<=9,Parameters!$B$14+(Parameters!$B$15-Parameters!$B$14)*POWER((A13-5)/4,2),Parameters!$B$16)) -> 0.65 | F13: =IF(A13<Parameters!$B$6,Parameters!$B$18*POWER(Parameters!$B$19,A13-1),0) -> 1525.8789
A14: 10 | B14: =Parameters!$B$34 -> Causal Horizon | C14: =Parameters!$B$5*POWER(Parameters!$B$7,A14-1)/IF(Parameters!$B$7=1,Parameters!$B$6,(POWER(Parameters!$B$7,Parameters!$B$6)-1)/(Parameters!$B$7-1)) -> 148.04673 | D14: =SUM(C$5:C14) -> 595 | E14: =IF(A14<=5,Parameters!$B$13+(Parameters!$B$14-Parameters!$B$13)*POWER((A14-1)/4,2),IF(A14<=9,Parameters!$B$14+(Parameters!$B$15-Parameters!$B$14)*POWER((A14-5)/4,2),Parameters!$B$16)) -> 0.7 | F14: =IF(A14<Parameters!$B$6,Parameters!$B$18*POWER(Parameters!$B$19,A14-1),0) -> 0 | G14: Endgame.
A15: TOTAL | C15: =SUM(C5:C14) -> 595 | F15: =SUM(F5:F14) -> 2542.4648

Sheet UpgradeSim
A1: UpgradeSim — Tier 1 (Solar System)
A2: 10-second tick simulation. Game ticks every 1 second under the hood; sim runs the COMPLETION path. See row 3 for headline timing metrics.
A3: Earliest possible transition (cohesion ready): | E3: =IFERROR(INDEX(B:B,MATCH(1,AO:AO,0))&" min","—") -> 5.16666666666667 min | H3: Actual transition (completion path): | M3: =IFERROR(INDEX(B:B,MATCH("transition",U:U,0))&" min","—") -> 8.5 min
A4: Tick | B4: Time (min) | C4: Mass start | D4: Cohesion | E4: SW | F4: AB | G4: SC | H4: Mag | I4: OR | J4: HP | K4: FP | L4: T2? | M4: MPC | N4: MPS | O4: APS | P4: Click inc | Q4: Auto inc | R4: Pass inc | S4: Total inc | T4: Mass post-inc | U4: Buy? | V4: Cost | W4: Coh + | X4: Mass end | Y4: M/sec | Z4: Note | AA4: SW M/min | AB4: AB M/min | AC4: SC M/min | AD4: Mag M/min | AE4: FP M/min | AF4: Base M/min | AG4: SW cost | AH4: AB cost | AI4: SC cost | AJ4: Mag cost | AK4: OR cost | AL4: HP cost | AM4: FP cost | AN4: Trans? | AO4: Could-trans? | AP4: Next OS cost | AQ4: Cheapest stack | AR4: Save mode | AS4: SW VPC | AT4: AB VPC | AU4: SC VPC | AV4: Mag VPC | AW4: Next OS VPC | AX4: Action
A5: 0 | B5: 0 | C5: 0 | D5: 0 | E5: 0 | F5: 0 | G5: 0 | H5: 0 | I5: 0 | J5: 0 | K5: 0 | L5: 0 | M5: =(Parameters!$B$9+(IF(E5=0,0,(Upgrades!$J$6+E5*Upgrades!$K$6)*POWER(Upgrades!$L$6,E5)))*(IF(Upgrades!$T$7="Solar Wind",POWER(Upgrades!$U$7,F5),1)*IF(Upgrades!$T$8="Solar Wind",POWER(Upgrades!$U$8,G5),1)*IF(Upgrades!$T$9="Solar Wind",POWER(Upgrades!$U$9,H5),1)*IF(Upgrades!$T$10="Solar Wind",POWER(Upgrades!$U$10,I5),1)*IF(Upgrades!$T$11="Solar Wind",POWER(Upgrades!$U$11,J5),1)*IF(Upgrades!$T$12="Solar Wind",POWER(Upgrades!$U$12,K5),1))+(IF(F5=0,0,(Upgrades!$J$7+F5*Upgrades!$K$7)*POWER(Upgrades!$L$7,F5)))*(IF(Upgrades!$T$6="Asteroid Belt",POWER(Upgrades!$U$6,E5),1)*IF(Upgrades!$T$8="Asteroid Belt",POWER(Upgrades!$U$8,G5),1)*IF(Upgrades!$T$9="Asteroid Belt",POWER(Upgrades!$U$9,H5),1)*IF(Upgrades!$T$10="Asteroid Belt",POWER(Upgrades!$U$10,I5),1)*IF(Upgrades!$T$11="Asteroid Belt",POWER(Upgrades!$U$11,J5),1)*IF(Upgrades!$T$12="Asteroid Belt",POWER(Upgrades!$U$12,K5),1))+(IF(G5=0,0,(Upgrades!$J$8+G5*Upgrades!$K$8)*POWER(Upgrades!$L$8,G5)))*(IF(Upgrades!$T$6="Stellar Coupling",POWER(Upgrades!$U$6,E5),1)*IF(Upgrades!$T$7="Stellar Coupling",POWER(Upgrades!$U$7,F5),1)*IF(Upgrades!$T$9="Stellar Coupling",POWER(Upgrades!$U$9,H5),1)*IF(Upgrades!$T$10="Stellar Coupling",POWER(Upgrades!$U$10,I5),1)*IF(Upgrades!$T$11="Stellar Coupling",POWER(Upgrades!$U$11,J5),1)*IF(Upgrades!$T$12="Stellar Coupling",POWER(Upgrades!$U$12,K5),1))+(IF(H5=0,0,(Upgrades!$J$9+H5*Upgrades!$K$9)*POWER(Upgrades!$L$9,H5)))*(IF(Upgrades!$T$6="Magnetosphere",POWER(Upgrades!$U$6,E5),1)*IF(Upgrades!$T$7="Magnetosphere",POWER(Upgrades!$U$7,F5),1)*IF(Upgrades!$T$8="Magnetosphere",POWER(Upgrades!$U$8,G5),1)*IF(Upgrades!$T$10="Magnetosphere",POWER(Upgrades!$U$10,I5),1)*IF(Upgrades!$T$11="Magnetosphere",POWER(Upgrades!$U$11,J5),1)*IF(Upgrades!$T$12="Magnetosphere",POWER(Upgrades!$U$12,K5),1))+(IF(I5=0,0,(Upgrades!$J$10+I5*Upgrades!$K$10)*POWER(Upgrades!$L$10,I5)))*(IF(Upgrades!$T$6="Orbital Resonance",POWER(Upgrades!$U$6,E5),1)*IF(Upgrades!$T$7="Orbital Resonance",POWER(Upgrades!$U$7,F5),1)*IF(Upgrades!$T$8="Orbital Resonance",POWER(Upgrades!$U$8,G5),1)*IF(Upgrades!$T$9="Orbital Resonance",POWER(Upgrades!$U$9,H5),1)*IF(Upgrades!$T$11="Orbital Resonance",POWER(Upgrades!$U$11,J5),1)*IF(Upgrades!$T$12="Orbital Resonance",POWER(Upgrades!$U$12,K5),1))+(IF(J5=0,0,(Upgrades!$J$11+J5*Upgrades!$K$11)*POWER(Upgrades!$L$11,J5)))*(IF(Upgrades!$T$6="Heliopause",POWER(Upgrades!$U$6,E5),1)*IF(Upgrades!$T$7="Heliopause",POWER(Upgrades!$U$7,F5),1)*IF(Upgrades!$T$8="Heliopause",POWER(Upgrades!$U$8,G5),1)*IF(Upgrades!$T$9="Heliopause",POWER(Upgrades!$U$9,H5),1)*IF(Upgrades!$T$10="Heliopause",POWER(Upgrades!$U$10,I5),1)*IF(Upgrades!$T$12="Heliopause",POWER(Upgrades!$U$12,K5),1))+(IF(K5=0,0,(Upgrades!$J$12+K5*Upgrades!$K$12)*POWER(Upgrades!$L$12,K5)))*(IF(Upgrades!$T$6="First Photons",POWER(Upgrades!$U$6,E5),1)*IF(Upgrades!$T$7="First Photons",POWER(Upgrades!$U$7,F5),1)*IF(Upgrades!$T$8="First Photons",POWER(Upgrades!$U$8,G5),1)*IF(Upgrades!$T$9="First Photons",POWER(Upgrades!$U$9,H5),1)*IF(Upgrades!$T$10="First Photons",POWER(Upgrades!$U$10,I5),1)*IF(Upgrades!$T$11="First Photons",POWER(Upgrades!$U$11,J5),1)))*POWER(Upgrades!$Q$6,E5)*POWER(Upgrades!$Q$7,F5)*POWER(Upgrades!$Q$8,G5)*POWER(Upgrades!$Q$9,H5)*POWER(Upgrades!$Q$10,I5)*POWER(Upgrades!$Q$11,J5)*POWER(Upgrades!$Q$12,K5) -> 1 | N5: =((IF(E5=0,0,(Upgrades!$G$6+E5*Upgrades!$H$6)*POWER(Upgrades!$I$6,E5)))*(IF(Upgrades!$T$7="Solar Wind",POWER(Upgrades!$U$7,F5),1)*IF(Upgrades!$T$8="Solar Wind",POWER(Upgrades!$U$8,G5),1)*IF(Upgrades!$T$9="Solar Wind",POWER(Upgrades!$U$9,H5),1)*IF(Upgrades!$T$10="Solar Wind",POWER(Upgrades!$U$10,I5),1)*IF(Upgrades!$T$11="Solar Wind",POWER(Upgrades!$U$11,J5),1)*IF(Upgrades!$T$12="Solar Wind",POWER(Upgrades!$U$12,K5),1))+(IF(F5=0,0,(Upgrades!$G$7+F5*Upgrades!$H$7)*POWER(Upgrades!$I$7,F5)))*(IF(Upgrades!$T$6="Asteroid Belt",POWER(Upgrades!$U$6,E5),1)*IF(Upgrades!$T$8="Asteroid Belt",POWER(Upgrades!$U$8,G5),1)*IF(Upgrades!$T$9="Asteroid Belt",POWER(Upgrades!$U$9,H5),1)*IF(Upgrades!$T$10="Asteroid Belt",POWER(Upgrades!$U$10,I5),1)*IF(Upgrades!$T$11="Asteroid Belt",POWER(Upgrades!$U$11,J5),1)*IF(Upgrades!$T$12="Asteroid Belt",POWER(Upgrades!$U$12,K5),1))+(IF(G5=0,0,(Upgrades!$G$8+G5*Upgrades!$H$8)*POWER(Upgrades!$I$8,G5)))*(IF(Upgrades!$T$6="Stellar Coupling",POWER(Upgrades!$U$6,E5),1)*IF(Upgrades!$T$7="Stellar Coupling",POWER(Upgrades!$U$7,F5),1)*IF(Upgrades!$T$9="Stellar Coupling",POWER(Upgrades!$U$9,H5),1)*IF(Upgrades!$T$10="Stellar Coupling",POWER(Upgrades!$U$10,I5),1)*IF(Upgrades!$T$11="Stellar Coupling",POWER(Upgrades!$U$11,J5),1)*IF(Upgrades!$T$12="Stellar Coupling",POWER(Upgrades!$U$12,K5),1))+(IF(H5=0,0,(Upgrades!$G$9+H5*Upgrades!$H$9)*POWER(Upgrades!$I$9,H5)))*(IF(Upgrades!$T$6="Magnetosphere",POWER(Upgrades!$U$6,E5),1)*IF(Upgrades!$T$7="Magnetosphere",POWER(Upgrades!$U$7,F5),1)*IF(Upgrades!$T$8="Magnetosphere",POWER(Upgrades!$U$8,G5),1)*IF(Upgrades!$T$10="Magnetosphere",POWER(Upgrades!$U$10,I5),1)*IF(Upgrades!$T$11="Magnetosphere",POWER(Upgrades!$U$11,J5),1)*IF(Upgrades!$T$12="Magnetosphere",POWER(Upgrades!$U$12,K5),1))+(IF(I5=0,0,(Upgrades!$G$10+I5*Upgrades!$H$10)*POWER(Upgrades!$I$10,I5)))*(IF(Upgrades!$T$6="Orbital Resonance",POWER(Upgrades!$U$6,E5),1)*IF(Upgrades!$T$7="Orbital Resonance",POWER(Upgrades!$U$7,F5),1)*IF(Upgrades!$T$8="Orbital Resonance",POWER(Upgrades!$U$8,G5),1)*IF(Upgrades!$T$9="Orbital Resonance",POWER(Upgrades!$U$9,H5),1)*IF(Upgrades!$T$11="Orbital Resonance",POWER(Upgrades!$U$11,J5),1)*IF(Upgrades!$T$12="Orbital Resonance",POWER(Upgrades!$U$12,K5),1))+(IF(J5=0,0,(Upgrades!$G$11+J5*Upgrades!$H$11)*POWER(Upgrades!$I$11,J5)))*(IF(Upgrades!$T$6="Heliopause",POWER(Upgrades!$U$6,E5),1)*IF(Upgrades!$T$7="Heliopause",POWER(Upgrades!$U$7,F5),1)*IF(Upgrades!$T$8="Heliopause",POWER(Upgrades!$U$8,G5),1)*IF(Upgrades!$T$9="Heliopause",POWER(Upgrades!$U$9,H5),1)*IF(Upgrades!$T$10="Heliopause",POWER(Upgrades!$U$10,I5),1)*IF(Upgrades!$T$12="Heliopause",POWER(Upgrades!$U$12,K5),1))+(IF(K5=0,0,(Upgrades!$G$12+K5*Upgrades!$H$12)*POWER(Upgrades!$I$12,K5)))*(IF(Upgrades!$T$6="First Photons",POWER(Upgrades!$U$6,E5),1)*IF(Upgrades!$T$7="First Photons",POWER(Upgrades!$U$7,F5),1)*IF(Upgrades!$T$8="First Photons",POWER(Upgrades!$U$8,G5),1)*IF(Upgrades!$T$9="First Photons",POWER(Upgrades!$U$9,H5),1)*IF(Upgrades!$T$10="First Photons",POWER(Upgrades!$U$10,I5),1)*IF(Upgrades!$T$11="First Photons",POWER(Upgrades!$U$11,J5),1)))*POWER(Upgrades!$P$6,E5)*POWER(Upgrades!$P$7,F5)*POWER(Upgrades!$P$8,G5)*POWER(Upgrades!$P$9,H5)*POWER(Upgrades!$P$10,I5)*POWER(Upgrades!$P$11,J5)*POWER(Upgrades!$P$12,K5) -> 0 | O5: =((IF(E5=0,0,(Upgrades!$M$6+E5*Upgrades!$N$6)*POWER(Upgrades!$O$6,E5)))*(IF(Upgrades!$T$7="Solar Wind",POWER(Upgrades!$U$7,F5),1)*IF(Upgrades!$T$8="Solar Wind",POWER(Upgrades!$U$8,G5),1)*IF(Upgrades!$T$9="Solar Wind",POWER(Upgrades!$U$9,H5),1)*IF(Upgrades!$T$10="Solar Wind",POWER(Upgrades!$U$10,I5),1)*IF(Upgrades!$T$11="Solar Wind",POWER(Upgrades!$U$11,J5),1)*IF(Upgrades!$T$12="Solar Wind",POWER(Upgrades!$U$12,K5),1))+(IF(F5=0,0,(Upgrades!$M$7+F5*Upgrades!$N$7)*POWER(Upgrades!$O$7,F5)))*(IF(Upgrades!$T$6="Asteroid Belt",POWER(Upgrades!$U$6,E5),1)*IF(Upgrades!$T$8="Asteroid Belt",POWER(Upgrades!$U$8,G5),1)*IF(Upgrades!$T$9="Asteroid Belt",POWER(Upgrades!$U$9,H5),1)*IF(Upgrades!$T$10="Asteroid Belt",POWER(Upgrades!$U$10,I5),1)*IF(Upgrades!$T$11="Asteroid Belt",POWER(Upgrades!$U$11,J5),1)*IF(Upgrades!$T$12="Asteroid Belt",POWER(Upgrades!$U$12,K5),1))+(IF(G5=0,0,(Upgrades!$M$8+G5*Upgrades!$N$8)*POWER(Upgrades!$O$8,G5)))*(IF(Upgrades!$T$6="Stellar Coupling",POWER(Upgrades!$U$6,E5),1)*IF(Upgrades!$T$7="Stellar Coupling",POWER(Upgrades!$U$7,F5),1)*IF(Upgrades!$T$9="Stellar Coupling",POWER(Upgrades!$U$9,H5),1)*IF(Upgrades!$T$10="Stellar Coupling",POWER(Upgrades!$U$10,I5),1)*IF(Upgrades!$T$11="Stellar Coupling",POWER(Upgrades!$U$11,J5),1)*IF(Upgrades!$T$12="Stellar Coupling",POWER(Upgrades!$U$12,K5),1))+(IF(H5=0,0,(Upgrades!$M$9+H5*Upgrades!$N$9)*POWER(Upgrades!$O$9,H5)))*(IF(Upgrades!$T$6="Magnetosphere",POWER(Upgrades!$U$6,E5),1)*IF(Upgrades!$T$7="Magnetosphere",POWER(Upgrades!$U$7,F5),1)*IF(Upgrades!$T$8="Magnetosphere",POWER(Upgrades!$U$8,G5),1)*IF(Upgrades!$T$10="Magnetosphere",POWER(Upgrades!$U$10,I5),1)*IF(Upgrades!$T$11="Magnetosphere",POWER(Upgrades!$U$11,J5),1)*IF(Upgrades!$T$12="Magnetosphere",POWER(Upgrades!$U$12,K5),1))+(IF(I5=0,0,(Upgrades!$M$10+I5*Upgrades!$N$10)*POWER(Upgrades!$O$10,I5)))*(IF(Upgrades!$T$6="Orbital Resonance",POWER(Upgrades!$U$6,E5),1)*IF(Upgrades!$T$7="Orbital Resonance",POWER(Upgrades!$U$7,F5),1)*IF(Upgrades!$T$8="Orbital Resonance",POWER(Upgrades!$U$8,G5),1)*IF(Upgrades!$T$9="Orbital Resonance",POWER(Upgrades!$U$9,H5),1)*IF(Upgrades!$T$11="Orbital Resonance",POWER(Upgrades!$U$11,J5),1)*IF(Upgrades!$T$12="Orbital Resonance",POWER(Upgrades!$U$12,K5),1))+(IF(J5=0,0,(Upgrades!$M$11+J5*Upgrades!$N$11)*POWER(Upgrades!$O$11,J5)))*(IF(Upgrades!$T$6="Heliopause",POWER(Upgrades!$U$6,E5),1)*IF(Upgrades!$T$7="Heliopause",POWER(Upgrades!$U$7,F5),1)*IF(Upgrades!$T$8="Heliopause",POWER(Upgrades!$U$8,G5),1)*IF(Upgrades!$T$9="Heliopause",POWER(Upgrades!$U$9,H5),1)*IF(Upgrades!$T$10="Heliopause",POWER(Upgrades!$U$10,I5),1)*IF(Upgrades!$T$12="Heliopause",POWER(Upgrades!$U$12,K5),1))+(IF(K5=0,0,(Upgrades!$M$12+K5*Upgrades!$N$12)*POWER(Upgrades!$O$12,K5)))*(IF(Upgrades!$T$6="First Photons",POWER(Upgrades!$U$6,E5),1)*IF(Upgrades!$T$7="First Photons",POWER(Upgrades!$U$7,F5),1)*IF(Upgrades!$T$8="First Photons",POWER(Upgrades!$U$8,G5),1)*IF(Upgrades!$T$9="First Photons",POWER(Upgrades!$U$9,H5),1)*IF(Upgrades!$T$10="First Photons",POWER(Upgrades!$U$10,I5),1)*IF(Upgrades!$T$11="First Photons",POWER(Upgrades!$U$11,J5),1)))*POWER(Upgrades!$R$6,E5)*POWER(Upgrades!$R$7,F5)*POWER(Upgrades!$R$8,G5)*POWER(Upgrades!$R$9,H5)*POWER(Upgrades!$R$10,I5)*POWER(Upgrades!$R$11,J5)*POWER(Upgrades!$R$12,K5) -> 0 | P5: 0 | Q5: 0 | R5: 0 | S5: 0 | T5: 0 | V5: 0 | W5: 0 | X5: 0 | Y5: =M5*Parameters!$B$10/60*Parameters!$B$11+O5*M5+N5 -> 1.6666667 | Z5: game start | AA5: =(IF(E5=0,0,(Upgrades!$G$6+E5*Upgrades!$H$6)*POWER(Upgrades!$I$6,E5)))*(IF(Upgrades!$T$7="Solar Wind",POWER(Upgrades!$U$7,F5),1)*IF(Upgrades!$T$8="Solar Wind",POWER(Upgrades!$U$8,G5),1)*IF(Upgrades!$T$9="Solar Wind",POWER(Upgrades!$U$9,H5),1)*IF(Upgrades!$T$10="Solar Wind",POWER(Upgrades!$U$10,I5),1)*IF(Upgrades!$T$11="Solar Wind",POWER(Upgrades!$U$11,J5),1)*IF(Upgrades!$T$12="Solar Wind",POWER(Upgrades!$U$12,K5),1))*POWER(Upgrades!$P$6,E5)*POWER(Upgrades!$P$7,F5)*POWER(Upgrades!$P$8,G5)*POWER(Upgrades!$P$9,H5)*POWER(Upgrades!$P$10,I5)*POWER(Upgrades!$P$11,J5)*POWER(Upgrades!$P$12,K5)*60 -> 0 | AB5: =(IF(F5=0,0,(Upgrades!$G$7+F5*Upgrades!$H$7)*POWER(Upgrades!$I$7,F5)))*(IF(Upgrades!$T$6="Asteroid Belt",POWER(Upgrades!$U$6,E5),1)*IF(Upgrades!$T$8="Asteroid Belt",POWER(Upgrades!$U$8,G5),1)*IF(Upgrades!$T$9="Asteroid Belt",POWER(Upgrades!$U$9,H5),1)*IF(Upgrades!$T$10="Asteroid Belt",POWER(Upgrades!$U$10,I5),1)*IF(Upgrades!$T$11="Asteroid Belt",POWER(Upgrades!$U$11,J5),1)*IF(Upgrades!$T$12="Asteroid Belt",POWER(Upgrades!$U$12,K5),1))*POWER(Upgrades!$P$6,E5)*POWER(Upgrades!$P$7,F5)*POWER(Upgrades!$P$8,G5)*POWER(Upgrades!$P$9,H5)*POWER(Upgrades!$P$10,I5)*POWER(Upgrades!$P$11,J5)*POWER(Upgrades!$P$12,K5)*60 -> 0 | AC5: =(IF(G5=0,0,(Upgrades!$J$8+G5*Upgrades!$K$8)*POWER(Upgrades!$L$8,G5)))*(IF(Upgrades!$T$6="Stellar Coupling",POWER(Upgrades!$U$6,E5),1)*IF(Upgrades!$T$7="Stellar Coupling",POWER(Upgrades!$U$7,F5),1)*IF(Upgrades!$T$9="Stellar Coupling",POWER(Upgrades!$U$9,H5),1)*IF(Upgrades!$T$10="Stellar Coupling",POWER(Upgrades!$U$10,I5),1)*IF(Upgrades!$T$11="Stellar Coupling",POWER(Upgrades!$U$11,J5),1)*IF(Upgrades!$T$12="Stellar Coupling",POWER(Upgrades!$U$12,K5),1))*POWER(Upgrades!$Q$6,E5)*POWER(Upgrades!$Q$7,F5)*POWER(Upgrades!$Q$8,G5)*POWER(Upgrades!$Q$9,H5)*POWER(Upgrades!$Q$10,I5)*POWER(Upgrades!$Q$11,J5)*POWER(Upgrades!$Q$12,K5)*Parameters!$B$10*Parameters!$B$11 -> 0 | AD5: =(IF(H5=0,0,(Upgrades!$G$9+H5*Upgrades!$H$9)*POWER(Upgrades!$I$9,H5)))*(IF(Upgrades!$T$6="Magnetosphere",POWER(Upgrades!$U$6,E5),1)*IF(Upgrades!$T$7="Magnetosphere",POWER(Upgrades!$U$7,F5),1)*IF(Upgrades!$T$8="Magnetosphere",POWER(Upgrades!$U$8,G5),1)*IF(Upgrades!$T$10="Magnetosphere",POWER(Upgrades!$U$10,I5),1)*IF(Upgrades!$T$11="Magnetosphere",POWER(Upgrades!$U$11,J5),1)*IF(Upgrades!$T$12="Magnetosphere",POWER(Upgrades!$U$12,K5),1))*POWER(Upgrades!$P$6,E5)*POWER(Upgrades!$P$7,F5)*POWER(Upgrades!$P$8,G5)*POWER(Upgrades!$P$9,H5)*POWER(Upgrades!$P$10,I5)*POWER(Upgrades!$P$11,J5)*POWER(Upgrades!$P$12,K5)*60 -> 0 | AE5: =(IF(K5=0,0,(Upgrades!$G$12+K5*Upgrades!$H$12)*POWER(Upgrades!$I$12,K5)))*(IF(Upgrades!$T$6="First Photons",POWER(Upgrades!$U$6,E5),1)*IF(Upgrades!$T$7="First Photons",POWER(Upgrades!$U$7,F5),1)*IF(Upgrades!$T$8="First Photons",POWER(Upgrades!$U$8,G5),1)*IF(Upgrades!$T$9="First Photons",POWER(Upgrades!$U$9,H5),1)*IF(Upgrades!$T$10="First Photons",POWER(Upgrades!$U$10,I5),1)*IF(Upgrades!$T$11="First Photons",POWER(Upgrades!$U$11,J5),1))*POWER(Upgrades!$P$6,E5)*POWER(Upgrades!$P$7,F5)*POWER(Upgrades!$P$8,G5)*POWER(Upgrades!$P$9,H5)*POWER(Upgrades!$P$10,I5)*POWER(Upgrades!$P$11,J5)*POWER(Upgrades!$P$12,K5)*60 -> 0 | AF5: =Parameters!$B$9*POWER(Upgrades!$Q$6,E5)*POWER(Upgrades!$Q$7,F5)*POWER(Upgrades!$Q$8,G5)*POWER(Upgrades!$Q$9,H5)*POWER(Upgrades!$Q$10,I5)*POWER(Upgrades!$Q$11,J5)*POWER(Upgrades!$Q$12,K5)*(Parameters!$B$10*Parameters!$B$11+O5*60) -> 100 | AG5: =IF(E5>=Upgrades!$E$6,"",Upgrades!$C$6*POWER(Upgrades!$D$6,E5)) -> 7 | AH5: =IF(F5>=Upgrades!$E$7,"",Upgrades!$C$7*POWER(Upgrades!$D$7,F5)) -> 20 | AI5: =IF(G5>=Upgrades!$E$8,"",Upgrades!$C$8*POWER(Upgrades!$D$8,G5)) -> 22 | AJ5: =IF(H5>=Upgrades!$E$9,"",Upgrades!$C$9*POWER(Upgrades!$D$9,H5)) -> 80 | AK5: =IF(I5>=Upgrades!$E$10,"",Upgrades!$C$10*POWER(Upgrades!$D$10,I5)) -> 240 | AL5: =IF(J5>=Upgrades!$E$11,"",Upgrades!$C$11*POWER(Upgrades!$D$11,J5)) -> 575 | AM5: =IF(K5>=Upgrades!$E$12,"",Upgrades!$C$12*POWER(Upgrades!$D$12,K5)) -> 850 | AN5: =IF(AND(D5>=Parameters!$B$18,(H5>=Upgrades!$E$9)*(K5>=Upgrades!$E$12)=1,L5=0),1,"") | AO5: =IF(AND(D5>=Parameters!$B$18,L5=0),1,"") | AP5: =MIN(IF(ISNUMBER(AK5),AK5,9000000000000000),IF(ISNUMBER(AL5),AL5,9000000000000000),IF(ISNUMBER(AM5),AM5,9000000000000000)) -> 240 | AQ5: =MIN(IF(ISNUMBER(AG5),AG5,9000000000000000),IF(ISNUMBER(AH5),AH5,9000000000000000),IF(ISNUMBER(AI5),AI5,9000000000000000),IF(ISNUMBER(AJ5),AJ5,9000000000000000)) -> 7 | AR5: =FALSE() -> FALSE | AS5: 0 | AT5: 0 | AU5: 0 | AV5: 0 | AW5: 0
A6: 1 | B6: =A6*10/60 -> 0.16666667 | C6: =X5 -> 0 | D6: =D5+W5 -> 0 | E6: =E5+IF(U5="SW",1,0) -> 0 | F6: =F5+IF(U5="AB",1,0) -> 0 | G6: =G5+IF(U5="SC",1,0) -> 0 | H6: =H5+IF(U5="Mag",1,0) -> 0 | I6: =MAX(I5,IF(U5="OR",1,0)) -> 0 | J6: =MAX(J5,IF(U5="HP",1,0)) -> 0 | K6: =MAX(K5,IF(U5="FP",1,0)) -> 0 | L6: =MAX(L5,IF(U5="transition",1,0)) -> 0 | M6: =(Parameters!$B$9+(IF(E6=0,0,(Upgrades!$J$6+E6*Upgrades!$K$6)*POWER(Upgrades!$L$6,E6)))*(IF(Upgrades!$T$7="Solar Wind",POWER(Upgrades!$U$7,F6),1)*IF(Upgrades!$T$8="Solar Wind",POWER(Upgrades!$U$8,G6),1)*IF(Upgrades!$T$9="Solar Wind",POWER(Upgrades!$U$9,H6),1)*IF(Upgrades!$T$10="Solar Wind",POWER(Upgrades!$U$10,I6),1)*IF(Upgrades!$T$11="Solar Wind",POWER(Upgrades!$U$11,J6),1)*IF(Upgrades!$T$12="Solar Wind",POWER(Upgrades!$U$12,K6),1))+(IF(F6=0,0,(Upgrades!$J$7+F6*Upgrades!$K$7)*POWER(Upgrades!$L$7,F6)))*(IF(Upgrades!$T$6="Asteroid Belt",POWER(Upgrades!$U$6,E6),1)*IF(Upgrades!$T$8="Asteroid Belt",POWER(Upgrades!$U$8,G6),1)*IF(Upgrades!$T$9="Asteroid Belt",POWER(Upgrades!$U$9,H6),1)*IF(Upgrades!$T$10="Asteroid Belt",POWER(Upgrades!$U$10,I6),1)*IF(Upgrades!$T$11="Asteroid Belt",POWER(Upgrades!$U$11,J6),1)*IF(Upgrades!$T$12="Asteroid Belt",POWER(Upgrades!$U$12,K6),1))+(IF(G6=0,0,(Upgrades!$J$8+G6*Upgrades!$K$8)*POWER(Upgrades!$L$8,G6)))*(IF(Upgrades!$T$6="Stellar Coupling",POWER(Upgrades!$U$6,E6),1)*IF(Upgrades!$T$7="Stellar Coupling",POWER(Upgrades!$U$7,F6),1)*IF(Upgrades!$T$9="Stellar Coupling",POWER(Upgrades!$U$9,H6),1)*IF(Upgrades!$T$10="Stellar Coupling",POWER(Upgrades!$U$10,I6),1)*IF(Upgrades!$T$11="Stellar Coupling",POWER(Upgrades!$U$11,J6),1)*IF(Upgrades!$T$12="Stellar Coupling",POWER(Upgrades!$U$12,K6),1))+(IF(H6=0,0,(Upgrades!$J$9+H6*Upgrades!$K$9)*POWER(Upgrades!$L$9,H6)))*(IF(Upgrades!$T$6="Magnetosphere",POWER(Upgrades!$U$6,E6),1)*IF(Upgrades!$T$7="Magnetosphere",POWER(Upgrades!$U$7,F6),1)*IF(Upgrades!$T$8="Magnetosphere",POWER(Upgrades!$U$8,G6),1)*IF(Upgrades!$T$10="Magnetosphere",POWER(Upgrades!$U$10,I6),1)*IF(Upgrades!$T$11="Magnetosphere",POWER(Upgrades!$U$11,J6),1)*IF(Upgrades!$T$12="Magnetosphere",POWER(Upgrades!$U$12,K6),1))+(IF(I6=0,0,(Upgrades!$J$10+I6*Upgrades!$K$10)*POWER(Upgrades!$L$10,I6)))*(IF(Upgrades!$T$6="Orbital Resonance",POWER(Upgrades!$U$6,E6),1)*IF(Upgrades!$T$7="Orbital Resonance",POWER(Upgrades!$U$7,F6),1)*IF(Upgrades!$T$8="Orbital Resonance",POWER(Upgrades!$U$8,G6),1)*IF(Upgrades!$T$9="Orbital Resonance",POWER(Upgrades!$U$9,H6),1)*IF(Upgrades!$T$11="Orbital Resonance",POWER(Upgrades!$U$11,J6),1)*IF(Upgrades!$T$12="Orbital Resonance",POWER(Upgrades!$U$12,K6),1))+(IF(J6=0,0,(Upgrades!$J$11+J6*Upgrades!$K$11)*POWER(Upgrades!$L$11,J6)))*(IF(Upgrades!$T$6="Heliopause",POWER(Upgrades!$U$6,E6),1)*IF(Upgrades!$T$7="Heliopause",POWER(Upgrades!$U$7,F6),1)*IF(Upgrades!$T$8="Heliopause",POWER(Upgrades!$U$8,G6),1)*IF(Upgrades!$T$9="Heliopause",POWER(Upgrades!$U$9,H6),1)*IF(Upgrades!$T$10="Heliopause",POWER(Upgrades!$U$10,I6),1)*IF(Upgrades!$T$12="Heliopause",POWER(Upgrades!$U$12,K6),1))+(IF(K6=0,0,(Upgrades!$J$12+K6*Upgrades!$K$12)*POWER(Upgrades!$L$12,K6)))*(IF(Upgrades!$T$6="First Photons",POWER(Upgrades!$U$6,E6),1)*IF(Upgrades!$T$7="First Photons",POWER(Upgrades!$U$7,F6),1)*IF(Upgrades!$T$8="First Photons",POWER(Upgrades!$U$8,G6),1)*IF(Upgrades!$T$9="First Photons",POWER(Upgrades!$U$9,H6),1)*IF(Upgrades!$T$10="First Photons",POWER(Upgrades!$U$10,I6),1)*IF(Upgrades!$T$11="First Photons",POWER(Upgrades!$U$11,J6),1)))*POWER(Upgrades!$Q$6,E6)*POWER(Upgrades!$Q$7,F6)*POWER(Upgrades!$Q$8,G6)*POWER(Upgrades!$Q$9,H6)*POWER(Upgrades!$Q$10,I6)*POWER(Upgrades!$Q$11,J6)*POWER(Upgrades!$Q$12,K6) -> 1 | N6: =((IF(E6=0,0,(Upgrades!$G$6+E6*Upgrades!$H$6)*POWER(Upgrades!$I$6,E6)))*(IF(Upgrades!$T$7="Solar Wind",POWER(Upgrades!$U$7,F6),1)*IF(Upgrades!$T$8="Solar Wind",POWER(Upgrades!$U$8,G6),1)*IF(Upgrades!$T$9="Solar Wind",POWER(Upgrades!$U$9,H6),1)*IF(Upgrades!$T$10="Solar Wind",POWER(Upgrades!$U$10,I6),1)*IF(Upgrades!$T$11="Solar Wind",POWER(Upgrades!$U$11,J6),1)*IF(Upgrades!$T$12="Solar Wind",POWER(Upgrades!$U$12,K6),1))+(IF(F6=0,0,(Upgrades!$G$7+F6*Upgrades!$H$7)*POWER(Upgrades!$I$7,F6)))*(IF(Upgrades!$T$6="Asteroid Belt",POWER(Upgrades!$U$6,E6),1)*IF(Upgrades!$T$8="Asteroid Belt",POWER(Upgrades!$U$8,G6),1)*IF(Upgrades!$T$9="Asteroid Belt",POWER(Upgrades!$U$9,H6),1)*IF(Upgrades!$T$10="Asteroid Belt",POWER(Upgrades!$U$10,I6),1)*IF(Upgrades!$T$11="Asteroid Belt",POWER(Upgrades!$U$11,J6),1)*IF(Upgrades!$T$12="Asteroid Belt",POWER(Upgrades!$U$12,K6),1))+(IF(G6=0,0,(Upgrades!$G$8+G6*Upgrades!$H$8)*POWER(Upgrades!$I$8,G6)))*(IF(Upgrades!$T$6="Stellar Coupling",POWER(Upgrades!$U$6,E6),1)*IF(Upgrades!$T$7="Stellar Coupling",POWER(Upgrades!$U$7,F6),1)*IF(Upgrades!$T$9="Stellar Coupling",POWER(Upgrades!$U$9,H6),1)*IF(Upgrades!$T$10="Stellar Coupling",POWER(Upgrades!$U$10,I6),1)*IF(Upgrades!$T$11="Stellar Coupling",POWER(Upgrades!$U$11,J6),1)*IF(Upgrades!$T$12="Stellar Coupling",POWER(Upgrades!$U$12,K6),1))+(IF(H6=0,0,(Upgrades!$G$9+H6*Upgrades!$H$9)*POWER(Upgrades!$I$9,H6)))*(IF(Upgrades!$T$6="Magnetosphere",POWER(Upgrades!$U$6,E6),1)*IF(Upgrades!$T$7="Magnetosphere",POWER(Upgrades!$U$7,F6),1)*IF(Upgrades!$T$8="Magnetosphere",POWER(Upgrades!$U$8,G6),1)*IF(Upgrades!$T$10="Magnetosphere",POWER(Upgrades!$U$10,I6),1)*IF(Upgrades!$T$11="Magnetosphere",POWER(Upgrades!$U$11,J6),1)*IF(Upgrades!$T$12="Magnetosphere",POWER(Upgrades!$U$12,K6),1))+(IF(I6=0,0,(Upgrades!$G$10+I6*Upgrades!$H$10)*POWER(Upgrades!$I$10,I6)))*(IF(Upgrades!$T$6="Orbital Resonance",POWER(Upgrades!$U$6,E6),1)*IF(Upgrades!$T$7="Orbital Resonance",POWER(Upgrades!$U$7,F6),1)*IF(Upgrades!$T$8="Orbital Resonance",POWER(Upgrades!$U$8,G6),1)*IF(Upgrades!$T$9="Orbital Resonance",POWER(Upgrades!$U$9,H6),1)*IF(Upgrades!$T$11="Orbital Resonance",POWER(Upgrades!$U$11,J6),1)*IF(Upgrades!$T$12="Orbital Resonance",POWER(Upgrades!$U$12,K6),1))+(IF(J6=0,0,(Upgrades!$G$11+J6*Upgrades!$H$11)*POWER(Upgrades!$I$11,J6)))*(IF(Upgrades!$T$6="Heliopause",POWER(Upgrades!$U$6,E6),1)*IF(Upgrades!$T$7="Heliopause",POWER(Upgrades!$U$7,F6),1)*IF(Upgrades!$T$8="Heliopause",POWER(Upgrades!$U$8,G6),1)*IF(Upgrades!$T$9="Heliopause",POWER(Upgrades!$U$9,H6),1)*IF(Upgrades!$T$10="Heliopause",POWER(Upgrades!$U$10,I6),1)*IF(Upgrades!$T$12="Heliopause",POWER(Upgrades!$U$12,K6),1))+(IF(K6=0,0,(Upgrades!$G$12+K6*Upgrades!$H$12)*POWER(Upgrades!$I$12,K6)))*(IF(Upgrades!$T$6="First Photons",POWER(Upgrades!$U$6,E6),1)*IF(Upgrades!$T$7="First Photons",POWER(Upgrades!$U$7,F6),1)*IF(Upgrades!$T$8="First Photons",POWER(Upgrades!$U$8,G6),1)*IF(Upgrades!$T$9="First Photons",POWER(Upgrades!$U$9,H6),1)*IF(Upgrades!$T$10="First Photons",POWER(Upgrades!$U$10,I6),1)*IF(Upgrades!$T$11="First Photons",POWER(Upgrades!$U$11,J6),1)))*POWER(Upgrades!$P$6,E6)*POWER(Upgrades!$P$7,F6)*POWER(Upgrades!$P$8,G6)*POWER(Upgrades!$P$9,H6)*POWER(Upgrades!$P$10,I6)*POWER(Upgrades!$P$11,J6)*POWER(Upgrades!$P$12,K6) -> 0 | O6: =((IF(E6=0,0,(Upgrades!$M$6+E6*Upgrades!$N$6)*POWER(Upgrades!$O$6,E6)))*(IF(Upgrades!$T$7="Solar Wind",POWER(Upgrades!$U$7,F6),1)*IF(Upgrades!$T$8="Solar Wind",POWER(Upgrades!$U$8,G6),1)*IF(Upgrades!$T$9="Solar Wind",POWER(Upgrades!$U$9,H6),1)*IF(Upgrades!$T$10="Solar Wind",POWER(Upgrades!$U$10,I6),1)*IF(Upgrades!$T$11="Solar Wind",POWER(Upgrades!$U$11,J6),1)*IF(Upgrades!$T$12="Solar Wind",POWER(Upgrades!$U$12,K6),1))+(IF(F6=0,0,(Upgrades!$M$7+F6*Upgrades!$N$7)*POWER(Upgrades!$O$7,F6)))*(IF(Upgrades!$T$6="Asteroid Belt",POWER(Upgrades!$U$6,E6),1)*IF(Upgrades!$T$8="Asteroid Belt",POWER(Upgrades!$U$8,G6),1)*IF(Upgrades!$T$9="Asteroid Belt",POWER(Upgrades!$U$9,H6),1)*IF(Upgrades!$T$10="Asteroid Belt",POWER(Upgrades!$U$10,I6),1)*IF(Upgrades!$T$11="Asteroid Belt",POWER(Upgrades!$U$11,J6),1)*IF(Upgrades!$T$12="Asteroid Belt",POWER(Upgrades!$U$12,K6),1))+(IF(G6=0,0,(Upgrades!$M$8+G6*Upgrades!$N$8)*POWER(Upgrades!$O$8,G6)))*(IF(Upgrades!$T$6="Stellar Coupling",POWER(Upgrades!$U$6,E6),1)*IF(Upgrades!$T$7="Stellar Coupling",POWER(Upgrades!$U$7,F6),1)*IF(Upgrades!$T$9="Stellar Coupling",POWER(Upgrades!$U$9,H6),1)*IF(Upgrades!$T$10="Stellar Coupling",POWER(Upgrades!$U$10,I6),1)*IF(Upgrades!$T$11="Stellar Coupling",POWER(Upgrades!$U$11,J6),1)*IF(Upgrades!$T$12="Stellar Coupling",POWER(Upgrades!$U$12,K6),1))+(IF(H6=0,0,(Upgrades!$M$9+H6*Upgrades!$N$9)*POWER(Upgrades!$O$9,H6)))*(IF(Upgrades!$T$6="Magnetosphere",POWER(Upgrades!$U$6,E6),1)*IF(Upgrades!$T$7="Magnetosphere",POWER(Upgrades!$U$7,F6),1)*IF(Upgrades!$T$8="Magnetosphere",POWER(Upgrades!$U$8,G6),1)*IF(Upgrades!$T$10="Magnetosphere",POWER(Upgrades!$U$10,I6),1)*IF(Upgrades!$T$11="Magnetosphere",POWER(Upgrades!$U$11,J6),1)*IF(Upgrades!$T$12="Magnetosphere",POWER(Upgrades!$U$12,K6),1))+(IF(I6=0,0,(Upgrades!$M$10+I6*Upgrades!$N$10)*POWER(Upgrades!$O$10,I6)))*(IF(Upgrades!$T$6="Orbital Resonance",POWER(Upgrades!$U$6,E6),1)*IF(Upgrades!$T$7="Orbital Resonance",POWER(Upgrades!$U$7,F6),1)*IF(Upgrades!$T$8="Orbital Resonance",POWER(Upgrades!$U$8,G6),1)*IF(Upgrades!$T$9="Orbital Resonance",POWER(Upgrades!$U$9,H6),1)*IF(Upgrades!$T$11="Orbital Resonance",POWER(Upgrades!$U$11,J6),1)*IF(Upgrades!$T$12="Orbital Resonance",POWER(Upgrades!$U$12,K6),1))+(IF(J6=0,0,(Upgrades!$M$11+J6*Upgrades!$N$11)*POWER(Upgrades!$O$11,J6)))*(IF(Upgrades!$T$6="Heliopause",POWER(Upgrades!$U$6,E6),1)*IF(Upgrades!$T$7="Heliopause",POWER(Upgrades!$U$7,F6),1)*IF(Upgrades!$T$8="Heliopause",POWER(Upgrades!$U$8,G6),1)*IF(Upgrades!$T$9="Heliopause",POWER(Upgrades!$U$9,H6),1)*IF(Upgrades!$T$10="Heliopause",POWER(Upgrades!$U$10,I6),1)*IF(Upgrades!$T$12="Heliopause",POWER(Upgrades!$U$12,K6),1))+(IF(K6=0,0,(Upgrades!$M$12+K6*Upgrades!$N$12)*POWER(Upgrades!$O$12,K6)))*(IF(Upgrades!$T$6="First Photons",POWER(Upgrades!$U$6,E6),1)*IF(Upgrades!$T$7="First Photons",POWER(Upgrades!$U$7,F6),1)*IF(Upgrades!$T$8="First Photons",POWER(Upgrades!$U$8,G6),1)*IF(Upgrades!$T$9="First Photons",POWER(Upgrades!$U$9,H6),1)*IF(Upgrades!$T$10="First Photons",POWER(Upgrades!$U$10,I6),1)*IF(Upgrades!$T$11="First Photons",POWER(Upgrades!$U$11,J6),1)))*POWER(Upgrades!$R$6,E6)*POWER(Upgrades!$R$7,F6)*POWER(Upgrades!$R$8,G6)*POWER(Upgrades!$R$9,H6)*POWER(Upgrades!$R$10,I6)*POWER(Upgrades!$R$11,J6)*POWER(Upgrades!$R$12,K6) -> 0 | P6: =IF(L6=1,0,M6*Parameters!$B$10/60*Parameters!$B$11*10) -> 16.666667 | Q6: =IF(L6=1,0,O6*M6*10) -> 0 | R6: =IF(L6=1,0,N6*10) -> 0 | S6: =P6+Q6+R6 -> 16.666667 | T6: =C6+S6 -> 16.666667 | U6: =AX6 | V6: =IF(U6="",0,IF(U6="transition",0,IF(U6="SW",AG6,IF(U6="AB",AH6,IF(U6="SC",AI6,IF(U6="Mag",AJ6,IF(U6="OR",AK6,IF(U6="HP",AL6,IF(U6="FP",AM6,0))))))))) -> 0 | W6: =IF(U6="OR",Upgrades!$F$10,IF(U6="HP",Upgrades!$F$11,IF(U6="transition",-Parameters!$B$18,0))) -> 0 | X6: =T6-V6 -> 16.666667 | Y6: =M6*Parameters!$B$10/60*Parameters!$B$11+O6*M6+N6 -> 1.6666667 | Z6: =IF(U6="transition","→ Tier 2 (Stellar Neighborhood)",IF(U6="FP","First Photons — light begins, system quickens",IF(U6="HP","Heliopause acquired",IF(U6="OR","Orbital Resonance — passive multiplier active",IF(AND(AO6=1,L6=0,AN6<>1),"Cohesion ready (waiting on completionist upgrades)",""))))) | AA6: =(IF(E6=0,0,(Upgrades!$G$6+E6*Upgrades!$H$6)*POWER(Upgrades!$I$6,E6)))*(IF(Upgrades!$T$7="Solar Wind",POWER(Upgrades!$U$7,F6),1)*IF(Upgrades!$T$8="Solar Wind",POWER(Upgrades!$U$8,G6),1)*IF(Upgrades!$T$9="Solar Wind",POWER(Upgrades!$U$9,H6),1)*IF(Upgrades!$T$10="Solar Wind",POWER(Upgrades!$U$10,I6),1)*IF(Upgrades!$T$11="Solar Wind",POWER(Upgrades!$U$11,J6),1)*IF(Upgrades!$T$12="Solar Wind",POWER(Upgrades!$U$12,K6),1))*POWER(Upgrades!$P$6,E6)*POWER(Upgrades!$P$7,F6)*POWER(Upgrades!$P$8,G6)*POWER(Upgrades!$P$9,H6)*POWER(Upgrades!$P$10,I6)*POWER(Upgrades!$P$11,J6)*POWER(Upgrades!$P$12,K6)*60 -> 0 | AB6: =(IF(F6=0,0,(Upgrades!$G$7+F6*Upgrades!$H$7)*POWER(Upgrades!$I$7,F6)))*(IF(Upgrades!$T$6="Asteroid Belt",POWER(Upgrades!$U$6,E6),1)*IF(Upgrades!$T$8="Asteroid Belt",POWER(Upgrades!$U$8,G6),1)*IF(Upgrades!$T$9="Asteroid Belt",POWER(Upgrades!$U$9,H6),1)*IF(Upgrades!$T$10="Asteroid Belt",POWER(Upgrades!$U$10,I6),1)*IF(Upgrades!$T$11="Asteroid Belt",POWER(Upgrades!$U$11,J6),1)*IF(Upgrades!$T$12="Asteroid Belt",POWER(Upgrades!$U$12,K6),1))*POWER(Upgrades!$P$6,E6)*POWER(Upgrades!$P$7,F6)*POWER(Upgrades!$P$8,G6)*POWER(Upgrades!$P$9,H6)*POWER(Upgrades!$P$10,I6)*POWER(Upgrades!$P$11,J6)*POWER(Upgrades!$P$12,K6)*60 -> 0 | AC6: =(IF(G6=0,0,(Upgrades!$J$8+G6*Upgrades!$K$8)*POWER(Upgrades!$L$8,G6)))*(IF(Upgrades!$T$6="Stellar Coupling",POWER(Upgrades!$U$6,E6),1)*IF(Upgrades!$T$7="Stellar Coupling",POWER(Upgrades!$U$7,F6),1)*IF(Upgrades!$T$9="Stellar Coupling",POWER(Upgrades!$U$9,H6),1)*IF(Upgrades!$T$10="Stellar Coupling",POWER(Upgrades!$U$10,I6),1)*IF(Upgrades!$T$11="Stellar Coupling",POWER(Upgrades!$U$11,J6),1)*IF(Upgrades!$T$12="Stellar Coupling",POWER(Upgrades!$U$12,K6),1))*POWER(Upgrades!$Q$6,E6)*POWER(Upgrades!$Q$7,F6)*POWER(Upgrades!$Q$8,G6)*POWER(Upgrades!$Q$9,H6)*POWER(Upgrades!$Q$10,I6)*POWER(Upgrades!$Q$11,J6)*POWER(Upgrades!$Q$12,K6)*Parameters!$B$10*Parameters!$B$11 -> 0 | AD6: =(IF(H6=0,0,(Upgrades!$G$9+H6*Upgrades!$H$9)*POWER(Upgrades!$I$9,H6)))*(IF(Upgrades!$T$6="Magnetosphere",POWER(Upgrades!$U$6,E6),1)*IF(Upgrades!$T$7="Magnetosphere",POWER(Upgrades!$U$7,F6),1)*IF(Upgrades!$T$8="Magnetosphere",POWER(Upgrades!$U$8,G6),1)*IF(Upgrades!$T$10="Magnetosphere",POWER(Upgrades!$U$10,I6),1)*IF(Upgrades!$T$11="Magnetosphere",POWER(Upgrades!$U$11,J6),1)*IF(Upgrades!$T$12="Magnetosphere",POWER(Upgrades!$U$12,K6),1))*POWER(Upgrades!$P$6,E6)*POWER(Upgrades!$P$7,F6)*POWER(Upgrades!$P$8,G6)*POWER(Upgrades!$P$9,H6)*POWER(Upgrades!$P$10,I6)*POWER(Upgrades!$P$11,J6)*POWER(Upgrades!$P$12,K6)*60 -> 0 | AE6: =(IF(K6=0,0,(Upgrades!$G$12+K6*Upgrades!$H$12)*POWER(Upgrades!$I$12,K6)))*(IF(Upgrades!$T$6="First Photons",POWER(Upgrades!$U$6,E6),1)*IF(Upgrades!$T$7="First Photons",POWER(Upgrades!$U$7,F6),1)*IF(Upgrades!$T$8="First Photons",POWER(Upgrades!$U$8,G6),1)*IF(Upgrades!$T$9="First Photons",POWER(Upgrades!$U$9,H6),1)*IF(Upgrades!$T$10="First Photons",POWER(Upgrades!$U$10,I6),1)*IF(Upgrades!$T$11="First Photons",POWER(Upgrades!$U$11,J6),1))*POWER(Upgrades!$P$6,E6)*POWER(Upgrades!$P$7,F6)*POWER(Upgrades!$P$8,G6)*POWER(Upgrades!$P$9,H6)*POWER(Upgrades!$P$10,I6)*POWER(Upgrades!$P$11,J6)*POWER(Upgrades!$P$12,K6)*60 -> 0 | AF6: =Parameters!$B$9*POWER(Upgrades!$Q$6,E6)*POWER(Upgrades!$Q$7,F6)*POWER(Upgrades!$Q$8,G6)*POWER(Upgrades!$Q$9,H6)*POWER(Upgrades!$Q$10,I6)*POWER(Upgrades!$Q$11,J6)*POWER(Upgrades!$Q$12,K6)*(Parameters!$B$10*Parameters!$B$11+O6*60) -> 100 | AG6: =IF(E6>=Upgrades!$E$6,"",Upgrades!$C$6*POWER(Upgrades!$D$6,E6)) -> 7 | AH6: =IF(F6>=Upgrades!$E$7,"",Upgrades!$C$7*POWER(Upgrades!$D$7,F6)) -> 20 | AI6: =IF(G6>=Upgrades!$E$8,"",Upgrades!$C$8*POWER(Upgrades!$D$8,G6)) -> 22 | AJ6: =IF(H6>=Upgrades!$E$9,"",Upgrades!$C$9*POWER(Upgrades!$D$9,H6)) -> 80 | AK6: =IF(I6>=Upgrades!$E$10,"",Upgrades!$C$10*POWER(Upgrades!$D$10,I6)) -> 240 | AL6: =IF(J6>=Upgrades!$E$11,"",Upgrades!$C$11*POWER(Upgrades!$D$11,J6)) -> 575 | AM6: =IF(K6>=Upgrades!$E$12,"",Upgrades!$C$12*POWER(Upgrades!$D$12,K6)) -> 850 | AN6: =IF(AND(D6>=Parameters!$B$18,(H6>=Upgrades!$E$9)*(K6>=Upgrades!$E$12)=1,L6=0),1,"") | AO6: =IF(AND(D6>=Parameters!$B$18,L6=0),1,"") | AP6: =MIN(IF(ISNUMBER(AK6),AK6,9000000000000000),IF(ISNUMBER(AL6),AL6,9000000000000000),IF(ISNUMBER(AM6),AM6,9000000000000000)) -> 240 | AQ6: =MIN(IF(ISNUMBER(AG6),AG6,9000000000000000),IF(ISNUMBER(AH6),AH6,9000000000000000),IF(ISNUMBER(AI6),AI6,9000000000000000),IF(ISNUMBER(AJ6),AJ6,9000000000000000)) -> 7 | AR6: =IF(AW6>Parameters!$B$21*(MAX(IF(AND(NOT(AND(AO6=1,AN6<>1)),ISNUMBER(AG6),AG6<=T6),AS6,0),IF(AND(NOT(AND(AO6=1,AN6<>1)),ISNUMBER(AH6),AH6<=T6),AT6,0),IF(AND(NOT(AND(AO6=1,AN6<>1)),ISNUMBER(AI6),AI6<=T6),AU6,0),IF(AND(ISNUMBER(AJ6),AJ6<=T6),AV6,0))),TRUE(),FALSE()) -> TRUE | AS6: =IFERROR(Upgrades!$H$6*(POWER(Upgrades!$P$6,E6)*POWER(Upgrades!$P$7,F6)*POWER(Upgrades!$P$8,G6)*POWER(Upgrades!$P$9,H6)*POWER(Upgrades!$P$10,I6)*POWER(Upgrades!$P$11,J6)*POWER(Upgrades!$P$12,K6))*(IF(Upgrades!$T$7="Solar Wind",POWER(Upgrades!$U$7,F6),1)*IF(Upgrades!$T$8="Solar Wind",POWER(Upgrades!$U$8,G6),1)*IF(Upgrades!$T$9="Solar Wind",POWER(Upgrades!$U$9,H6),1)*IF(Upgrades!$T$10="Solar Wind",POWER(Upgrades!$U$10,I6),1)*IF(Upgrades!$T$11="Solar Wind",POWER(Upgrades!$U$11,J6),1)*IF(Upgrades!$T$12="Solar Wind",POWER(Upgrades!$U$12,K6),1))/AG6,0) -> 0.011428571 | AT6: =IFERROR(Upgrades!$H$7*(POWER(Upgrades!$P$6,E6)*POWER(Upgrades!$P$7,F6)*POWER(Upgrades!$P$8,G6)*POWER(Upgrades!$P$9,H6)*POWER(Upgrades!$P$10,I6)*POWER(Upgrades!$P$11,J6)*POWER(Upgrades!$P$12,K6))*(IF(Upgrades!$T$6="Asteroid Belt",POWER(Upgrades!$U$6,E6),1)*IF(Upgrades!$T$8="Asteroid Belt",POWER(Upgrades!$U$8,G6),1)*IF(Upgrades!$T$9="Asteroid Belt",POWER(Upgrades!$U$9,H6),1)*IF(Upgrades!$T$10="Asteroid Belt",POWER(Upgrades!$U$10,I6),1)*IF(Upgrades!$T$11="Asteroid Belt",POWER(Upgrades!$U$11,J6),1)*IF(Upgrades!$T$12="Asteroid Belt",POWER(Upgrades!$U$12,K6),1))/AH6,0) -> 0.01 | AU6: =IFERROR(Upgrades!$K$8*(POWER(Upgrades!$Q$6,E6)*POWER(Upgrades!$Q$7,F6)*POWER(Upgrades!$Q$8,G6)*POWER(Upgrades!$Q$9,H6)*POWER(Upgrades!$Q$10,I6)*POWER(Upgrades!$Q$11,J6)*POWER(Upgrades!$Q$12,K6))*(IF(Upgrades!$T$6="Stellar Coupling",POWER(Upgrades!$U$6,E6),1)*IF(Upgrades!$T$7="Stellar Coupling",POWER(Upgrades!$U$7,F6),1)*IF(Upgrades!$T$9="Stellar Coupling",POWER(Upgrades!$U$9,H6),1)*IF(Upgrades!$T$10="Stellar Coupling",POWER(Upgrades!$U$10,I6),1)*IF(Upgrades!$T$11="Stellar Coupling",POWER(Upgrades!$U$11,J6),1)*IF(Upgrades!$T$12="Stellar Coupling",POWER(Upgrades!$U$12,K6),1))*Parameters!$B$10*Parameters!$B$11/60/AI6,0) -> 0.026515152 | AV6: =IFERROR(Upgrades!$H$9*(POWER(Upgrades!$P$6,E6)*POWER(Upgrades!$P$7,F6)*POWER(Upgrades!$P$8,G6)*POWER(Upgrades!$P$9,H6)*POWER(Upgrades!$P$10,I6)*POWER(Upgrades!$P$11,J6)*POWER(Upgrades!$P$12,K6))*(IF(Upgrades!$T$6="Magnetosphere",POWER(Upgrades!$U$6,E6),1)*IF(Upgrades!$T$7="Magnetosphere",POWER(Upgrades!$U$7,F6),1)*IF(Upgrades!$T$8="Magnetosphere",POWER(Upgrades!$U$8,G6),1)*IF(Upgrades!$T$10="Magnetosphere",POWER(Upgrades!$U$10,I6),1)*IF(Upgrades!$T$11="Magnetosphere",POWER(Upgrades!$U$11,J6),1)*IF(Upgrades!$T$12="Magnetosphere",POWER(Upgrades!$U$12,K6),1))/AJ6,0) -> 0.0125 | AW6: =MAX(IF(I6>0,0,IFERROR(0.25*N6/Upgrades!$C$10,0)),IF(J6>0,0,IFERROR(0.5*((IF(G6=0,0,(Upgrades!$J$8+G6*Upgrades!$K$8)*POWER(Upgrades!$L$8,G6)))*(IF(Upgrades!$T$6="Stellar Coupling",POWER(Upgrades!$U$6,E6),1)*IF(Upgrades!$T$7="Stellar Coupling",POWER(Upgrades!$U$7,F6),1)*IF(Upgrades!$T$9="Stellar Coupling",POWER(Upgrades!$U$9,H6),1)*IF(Upgrades!$T$10="Stellar Coupling",POWER(Upgrades!$U$10,I6),1)*IF(Upgrades!$T$11="Stellar Coupling",POWER(Upgrades!$U$11,J6),1)*IF(Upgrades!$T$12="Stellar Coupling",POWER(Upgrades!$U$12,K6),1))*(POWER(Upgrades!$Q$6,E6)*POWER(Upgrades!$Q$7,F6)*POWER(Upgrades!$Q$8,G6)*POWER(Upgrades!$Q$9,H6)*POWER(Upgrades!$Q$10,I6)*POWER(Upgrades!$Q$11,J6)*POWER(Upgrades!$Q$12,K6))*Parameters!$B$10*Parameters!$B$11/60)/Upgrades!$C$11,0)),IF(K6>0,0,IFERROR((1*(POWER(Upgrades!$P$6,E6)*POWER(Upgrades!$P$7,F6)*POWER(Upgrades!$P$8,G6)*POWER(Upgrades!$P$9,H6)*POWER(Upgrades!$P$10,I6)*POWER(Upgrades!$P$11,J6)*POWER(Upgrades!$P$12,K6))+0.2*M6*Parameters!$B$10*Parameters!$B$11/60)/Upgrades!$C$12,0)),IF(AND(ISNUMBER(AG6),AG6>T6),AS6,0),IF(AND(ISNUMBER(AH6),AH6>T6),AT6,0),IF(AND(ISNUMBER(AI6),AI6>T6),AU6,0),IF(AND(ISNUMBER(AJ6),AJ6>T6),AV6,0)) -> 0.026515152 | AX6: =IF(AN6=1,"transition",IF(MIN(IF(AND(I6=0,ISNUMBER(AK6),AK6<=T6),AK6,9000000000000000),IF(AND(J6=0,ISNUMBER(AL6),AL6<=T6),AL6,9000000000000000),IF(AND(K6=0,ISNUMBER(AM6),AM6<=T6),AM6,9000000000000000))<9000000000000000,IF(AND(AND(I6=0,ISNUMBER(AK6),AK6<=T6),AK6=MIN(IF(AND(I6=0,ISNUMBER(AK6),AK6<=T6),AK6,9000000000000000),IF(AND(J6=0,ISNUMBER(AL6),AL6<=T6),AL6,9000000000000000),IF(AND(K6=0,ISNUMBER(AM6),AM6<=T6),AM6,9000000000000000))),"OR",IF(AND(AND(J6=0,ISNUMBER(AL6),AL6<=T6),AL6=MIN(IF(AND(I6=0,ISNUMBER(AK6),AK6<=T6),AK6,9000000000000000),IF(AND(J6=0,ISNUMBER(AL6),AL6<=T6),AL6,9000000000000000),IF(AND(K6=0,ISNUMBER(AM6),AM6<=T6),AM6,9000000000000000))),"HP","FP")),IF(AR6=TRUE(),"",IF(MAX(IF(AND(NOT(AND(AO6=1,AN6<>1)),ISNUMBER(AG6),AG6<=T6),AS6,0),IF(AND(NOT(AND(AO6=1,AN6<>1)),ISNUMBER(AH6),AH6<=T6),AT6,0),IF(AND(NOT(AND(AO6=1,AN6<>1)),ISNUMBER(AI6),AI6<=T6),AU6,0),IF(AND(ISNUMBER(AJ6),AJ6<=T6),AV6,0))<=0,"",IF(AND(IF(AND(NOT(AND(AO6=1,AN6<>1)),ISNUMBER(AG6),AG6<=T6),AS6,0)>0,IF(AND(NOT(AND(AO6=1,AN6<>1)),ISNUMBER(AG6),AG6<=T6),AS6,0)=MAX(IF(AND(NOT(AND(AO6=1,AN6<>1)),ISNUMBER(AG6),AG6<=T6),AS6,0),IF(AND(NOT(AND(AO6=1,AN6<>1)),ISNUMBER(AH6),AH6<=T6),AT6,0),IF(AND(NOT(AND(AO6=1,AN6<>1)),ISNUMBER(AI6),AI6<=T6),AU6,0),IF(AND(ISNUMBER(AJ6),AJ6<=T6),AV6,0))),"SW",IF(AND(IF(AND(NOT(AND(AO6=1,AN6<>1)),ISNUMBER(AH6),AH6<=T6),AT6,0)>0,IF(AND(NOT(AND(AO6=1,AN6<>1)),ISNUMBER(AH6),AH6<=T6),AT6,0)=MAX(IF(AND(NOT(AND(AO6=1,AN6<>1)),ISNUMBER(AG6),AG6<=T6),AS6,0),IF(AND(NOT(AND(AO6=1,AN6<>1)),ISNUMBER(AH6),AH6<=T6),AT6,0),IF(AND(NOT(AND(AO6=1,AN6<>1)),ISNUMBER(AI6),AI6<=T6),AU6,0),IF(AND(ISNUMBER(AJ6),AJ6<=T6),AV6,0))),"AB",IF(AND(IF(AND(NOT(AND(AO6=1,AN6<>1)),ISNUMBER(AI6),AI6<=T6),AU6,0)>0,IF(AND(NOT(AND(AO6=1,AN6<>1)),ISNUMBER(AI6),AI6<=T6),AU6,0)=MAX(IF(AND(NOT(AND(AO6=1,AN6<>1)),ISNUMBER(AG6),AG6<=T6),AS6,0),IF(AND(NOT(AND(AO6=1,AN6<>1)),ISNUMBER(AH6),AH6<=T6),AT6,0),IF(AND(NOT(AND(AO6=1,AN6<>1)),ISNUMBER(AI6),AI6<=T6),AU6,0),IF(AND(ISNUMBER(AJ6),AJ6<=T6),AV6,0))),"SC","Mag")))))))
