Workbook

Sheet README
A1: Dark Filaments — Simulator v1.3
A2: Adds Tier 2 in a separate sheet (UpgradeSimT2) that consumes T1's exit state as carryover. T1 sheet is unchanged from v1.2.1. Greedy VPC + save threshold + post-cohesion focus strategy carries over.
A4: The three core stats
A5: • MPC — Mass per Click — affects active click income AND autoclicker output
A6: • MPS — Mass per Second — passive income rate
A7: • APS — Autoclicks per Second — fake clicks per second from autoclickers
A8: Game tick = 1 second. Total income/sec = (cpm/60 × MPC × active) + (APS × MPC) + MPS.
A9: Simulator measures in 10-second chunks (10 game ticks per sim row).
A11: Unified upgrade schema
A12: Every upgrade has the same fields. Most fields will be 0 (additive) or 1.0 (multiplicative) for any given upgrade — only the ones that actually do something get filled in.
A14: Per-stat fields (one set each for M/sec, M/click, AC/sec):
A15: • Base — constant value when level ≥ 1, before any multipliers
... A65: Yellow = editable input. Light green = derived live calculation. Black text = formula. Green text = cross-tab reference.

Sheet Parameters
A1: Parameters
A2: Edit yellow cells. Everything else updates automatically.
A4: Time budget
A5: Total target playtime (minutes) | B5: 595 | C5: Casual pace at 45 cpm. 60 cpm players will finish closer to ~480 min.
A6: Number of tiers | B6: 10 | C6: Solar System through Causal Horizon.
A7: Tier real-time growth rate | B7: 1.3 | C7: Each tier takes this many times as long as the previous one.
A8: Click & income
A9: Base click value (Mass per click, no upgrades) | B9: 1 | C9: The unit of the economy. Each click yields this much Mass with zero upgrades.
A10: Average clicks per minute when active | B10: 100 | C10: Reflects autoclicker / engaged play. Prototype dynamically reports actual cpm.
A11: Active play fraction (0–1) | B11: 1 | C11: Prototype reports cpm in real time, so this stays at 1.0; AFK time is captured by cpm dropping.
A12: Click importance curve (U-shape, diagnostic only)
A13: Click share at Tier 1 | B13: 0.6 | C13: Clicks dominate at start.
A14: Click share minimum (Tier 5 dip) | B14: 0.05 | C14: Crescendo — chain reactions handle nearly everything.
A15: Click share late game (Tier 9) | B15: 0.65 | C15: 'Hanging on.'
A16: Click share endgame (Tier 10) | B16: 0.7 | C16: Click becomes ritual.
A17: Cohesion (gates tier transitions)
A18: Cohesion cost: T1 → T2 transition | B18: 1 | C18: Tutorial-friendly.
A19: Cohesion cost growth per tier | B19: 2.5 | C19: Geometric growth.
A20: Simulator strategy
A21: VPC save threshold | B21: 1.5 | C21: Save mode triggers when next-target VPC > (best-affordable VPC × this). Lower = saves harder.
A22: Tier 2 carryover (from T1 exit state)
A23: T2 carryover mode (1=Completion, 0=Threshold) | B23: 1 | C23: 1: T1 fully completed (Mag=5, FP=1). 0: T1 cohesion met but completionists not maxed.
A24: Carry mass at T1 Completion-exit | B24: 315 | C24: Mass surplus when T1 finishes the completion path at 100 cpm.
A25: Carry mass at T1 Threshold-exit | B25: 80 | C25: Mass surplus when T1 just barely meets cohesion (Mag~2, FP=0).
A26: Carry MPS floor at Completion-exit | B26: 10.75 | C26: T1 final MPS contribution. Persists into T2 as a floor.
A27: Carry MPS floor at Threshold-exit | B27: 5.75 | C27: T1 partial MPS at threshold. Persists into T2 as a floor.
A28: Carry MPC floor at Completion-exit | B28: 4.98 | C28: T1 final MPC contribution including base click value × all multipliers.
A29: Carry MPC floor at Threshold-exit | B29: 4.15 | C29: T1 partial MPC including base click and active multipliers (no FP).
A30: Carry APS floor | B30: 0 | C30: T1 has no APS sources. Stays 0 until that changes.
A31: Carry × all M/sec at Completion-exit | B31: 1.25 | C31: OR active (×1.25). Continues to multiply T2 MPS contributions.
A32: Carry × all M/sec at Threshold-exit | B32: 1.25 | C32: OR active at threshold-exit (it's bought to reach cohesion 1.0).
A33: Carry × all M/click at Completion-exit | B33: 1.2 | C33: FP active (×1.20). Continues to multiply T2 MPC contributions.
A34: Carry × all M/click at Threshold-exit | B34: 1 | C34: FP not yet owned at threshold-exit.
A35: Carry × all AC speed | B35: 1 | C35: No T1 sources affect AC speed.
A36: Offline progression
A37: Offline progression rate (1.0 = full) | B37: 1 | C37: Full offline accumulation; queued events fire on return.
A38: Tier names
A39: Tier 1 name | B39: Solar System | C39: Tutorial.
A40: Tier 2 name | B40: Stellar Neighborhood | C40: First sense of scale. Introduces autoclickers.
A41: Tier 3 name | B41: Galactic Arm
...

Sheet Upgrades
A1: Upgrades — unified schema
A2: Each row is one upgrade. Yellow cells editable. Most cells will be 0 (additive) or 1.0 (multiplicative) — only the levers that actually do something get filled in. Completionist = missable upgrade. Synergy target/mult lets one upgrade buff another's self-contribution geometrically with level.
A4: Identity | C4: Cost & limits | G4: Self M/sec | J4: Self M/click | M4: Self AC/sec | P4: Global multipliers | S4: Completion | T4: Synergy | V4: Description
A5: Tier | B5: Name | C5: Init cost | D5: Cost growth | E5: Max levels | F5: Cohesion + | G5: Base | H5: + /lvl | I5: × self /lvl | J5: Base | K5: + /lvl | L5: × self /lvl | M5: Base | N5: + /lvl | O5: × self /lvl | P5: × all M/sec /lvl | Q5: × all M/click /lvl | R5: × all AC speed /lvl | S5: Completionist? | T5: Synergy target | U5: Synergy mult/lvl | V5: Description voice
A6: 1 | B6: Solar Wind | C6: 7 | D6: 1.15 | E6: 99 | F6: 0 | G6: 0 | H6: 0.08 | I6: 1 | J6: 0 | K6: 0 | L6: 1 | M6: 0 | N6: 0 | O6: 1 | P6: 1 | Q6: 1 | R6: 1 | S6: 0 | U6: 1 | V6: Charged particles drift outward and return with company. We are pulling more than we used to.
A7: 1 | B7: Asteroid Belt | C7: 20 | D7: 1.15 | E7: 99 | F7: 0 | G7: 0 | H7: 0.2 | I7: 1 | J7: 0 | K7: 0 | L7: 1 | M7: 0 | N7: 0 | O7: 1 | P7: 1 | Q7: 1 | R7: 1 | S7: 0 | U7: 1 | V7: The belt yields. Iron, ice, the slow gravel of the early system. Each rock finds us.
A8: 1 | B8: Stellar Coupling | C8: 22 | D8: 1.4 | E8: 99 | F8: 0 | G8: 0 | H8: 0 | I8: 1 | J8: 0 | K8: 0.35 | L8: 1 | M8: 0 | N8: 0 | O8: 1 | P8: 1 | Q8: 1 | R8: 1 | S8: 0 | U8: 1 | V8: We pull harder. The center holds tighter.
A9: 1 | B9: Magnetosphere | C9: 80 | D9: 2 | E9: 5 | F9: 0 | G9: 0 | H9: 1 | I9: 1 | J9: 0 | K9: 0 | L9: 1 | M9: 0 | N9: 0 | O9: 1 | P9: 1 | Q9: 1 | R9: 1 | S9: 1 | U9: 1 | V9: The system's invisible shell. Charged particles arc and return. We catch what would have escaped.
A10: 1 | B10: Orbital Resonance | C10: 240 | D10: 1 | E10: 1 | F10: 0.4 | G10: 0 | H10: 0 | I10: 1 | J10: 0 | K10: 0 | L10: 1 | M10: 0 | N10: 0 | O10: 1 | P10: 1.25 | Q10: 1 | R10: 1 | S10: 0 | U10: 1 | V10: Periods align. The system breathes in time with us. Everything we touch becomes synchronous.
A11: 1 | B11: Heliopause | C11: 575 | D11: 1 | E11: 1 | F11: 0.6 | G11: 0 | H11: 0 | I11: 1 | J11: 0 | K11: 0 | L11: 1 | M11: 0 | N11: 0 | O11: 1 | P11: 1 | Q11: 1 | R11: 1 | S11: 0 | T11: Stellar Coupling | U11: 1.5 | V11: We have reached the edge of our influence. Beyond it, the rest of the galaxy waits.
A12: 1 | B12: First Photons | C12: 850 | D12: 1 | E12: 1 | F12: 0 | G12: 1 | H12: 0 | I12: 1 | J12: 0 | K12: 0 | L12: 1 | M12: 0 | N12: 0 | O12: 1 | P12: 1 | Q12: 1.2 | R12: 1 | S12: 1 | U12: 1 | V12: Light, finally. The first photons leave the surface and find us. Everything quickens.
A13: 2 | B13: Stellar Kinematics | C13: 60 | D13: 1.15 | E13: 99 | F13: 0 | G13: 0 | H13: 0.65 | I13: 1 | J13: 0 | K13: 0 | L13: 1 | M13: 0 | N13: 0 | O13: 1 | P13: 1 | Q13: 1 | R13: 1 | S13: 0 | U13: 1 | V13: Stars drift in measured patterns. We learn to read the slow vectors of the neighborhood.
A14: 2 | B14: Local Bubble | C14: 180 | D14: 1.15 | E14: 99 | F14: 0 | G14: 0 | H14: 1.8 | I14: 1 | J14: 0 | K14: 0 | L14: 1 | M14: 0 | N14: 0 | O14: 1 | P14: 1 | Q14: 1 | R14: 1 | S14: 0 | U14: 1 | V14: An emptier pocket of the galaxy. Our reach extends through its low-density walls.
A15: 2 | B15: Microlensing | C15: 200 | D15: 1.4 | E15: 99 | F15: 0 | G15: 0 | H15: 0 | I15: 1 | J15: 0 | K15: 2.8 | L15: 1 | M15: 0 | N15: 0 | O15: 1 | P15: 1 | Q15: 1 | R15: 1 | S15: 0 | U15: 1 | V15: Distant light bends around mass we cannot see. Each event is a brief annunciation.
A16: 2 | B16: Roche Lobe Overflow | C16: 350 | D16: 1.5 | E16: 99 | F16: 0 | G16: 0 | H16: 0 | I16: 1 | J16: 0 | K16: 0 | L16: 1 | M16: 0 | N16: 0.1 | O16: 1 | P16: 1 | Q16: 1 | R16: 1 | S16: 0 | T16: Local Bubble | U16: 1.05 | V16: A companion star's outer envelope spills across the gravitational saddle. Material flows to us automatically.
A17: 2 | B17: Brown Dwarf | C17: 2000 | D17: 2 | E17: 5 | F17: 0 | G17: 0 | H17: 4 | I17: 1 | J17: 0 | K17: 0 | L17: 1 | M17: 0 | N17: 0 | O17: 1 | P17: 1 | Q17: 1 | R17: 1 | S17: 1 | T17: Roche Lobe Overflow | U17: 1.1 | V17: A failed star, never quite hot enough. We catalog it. Its weak gravity helps the lobes spill faster.
A18: 2 | B18: Binary Partner | C18: 1400 | D18: 1 | E18: 1 | F18: 0.6 | G18: 0 | H18: 0 | I18: 1 | J18: 0 | K18: 0 | L18: 1 | M18: 0 | N18: 0 | O18: 1 | P18: 1 | Q18: 1 | R18: 1 | S18: 0 | T18: Microlensing | U18: 1.5 | V18: We pair. The two-body orbit is mathematics made visible. Lensing events double when seen from a moving baseline.
A19: 2 | B19: Peculiar Velocity | C19: 2200 | D19: 1 | E19: 1 | F19: 0.9 | G19: 0 | H19: 0 | I19: 1 | J19: 0 | K19: 0 | L19: 1 | M19: 0 | N19: 0 | O19: 1 | P19: 1.3 | Q19: 1 | R19: 1 | S19: 0 | U19: 1 | V19: Above the Hubble flow we have our own motion. Everything drifts a little faster toward us.
A20: 2 | B20: Open Cluster | C20: 3400 | D20: 1 | E20: 1 | F20: 1 | G20: 0 | H20: 0 | I20: 1 | J20: 0 | K20: 0 | L20: 1 | M20: 0 | N20: 0 | O20: 1 | P20: 1 | Q20: 1 | R20: 1 | S20: 0 | U20: 1 | V20: Loose stars share a birth and a direction. We are no longer alone in our trajectory.
A21: 2 | B21: Moving Group | C21: 14000 | D21: 1 | E21: 1 | F21: 0 | G21: 6 | H21: 0 | I21: 1 | J21: 0 | K21: 0 | L21: 1 | M21: 0 | N21: 0 | O21: 1 | P21: 1 | Q21: 1.2 | R21: 1 | S21: 1 | U21: 1 | V21: The whole pocket drifts together — Hyades, Pleiades, kin we never named. We feel the current.

Sheet TimeBudget
A1: Time budget per tier
A2: Time targets and click share targets per tier. Derived from Parameters.
A4: Tier | B4: Name | C4: Min/tier | D4: Cum min | E4: Click % | F4: Cohesion cost | G4: Notes
A5: 1 | B5: =Parameters!$B$39 | C5: =Parameters!$B$5*POWER(Parameters!$B$7,A5-1)/IF(Parameters!$B$7=1,Parameters!$B$6,(POWER(Parameters!$B$7,Parameters!$B$6)-1)/(Parameters!$B$7-1)) | D5: =SUM(C$5:C5) | E5: =IF(A5<=5,Parameters!$B$13+(Parameters!$B$14-Parameters!$B$13)*POWER((A5-1)/4,2),IF(A5<=9,Parameters!$B$14+(Parameters!$B$15-Parameters!$B$14)*POWER((A5-5)/4,2),Parameters!$B$16)) | F5: =IF(A5<Parameters!$B$6,Parameters!$B$18*POWER(Parameters!$B$19,A5-1),0) | G5: Tutorial.
A6: 2 | B6: =Parameters!$B$40 | C6: =Parameters!$B$5*POWER(Parameters!$B$7,A6-1)/IF(Parameters!$B$7=1,Parameters!$B$6,(POWER(Parameters!$B$7,Parameters!$B$6)-1)/(Parameters!$B$7-1)) | D6: =SUM(C$5:C6) | E6: =IF(A6<=5,Parameters!$B$13+(Parameters!$B$14-Parameters!$B$13)*POWER((A6-1)/4,2),IF(A6<=9,Parameters!$B$14+(Parameters!$B$15-Parameters!$B$14)*POWER((A6-5)/4,2),Parameters!$B$16)) | F6: =IF(A6<Parameters!$B$6,Parameters!$B$18*POWER(Parameters!$B$19,A6-1),0) | G6: Autoclickers introduced.
A7: 3 | B7: =Parameters!$B$41 | C7: =Parameters!$B$5*POWER(Parameters!$B$7,A7-1)/IF(Parameters!$B$7=1,Parameters!$B$6,(POWER(Parameters!$B$7,Parameters!$B$6)-1)/(Parameters!$B$7-1)) | D7: =SUM(C$5:C7) | E7: =IF(A7<=5,Parameters!$B$13+(Parameters!$B$14-Parameters!$B$13)*POWER((A7-1)/4,2),IF(A7<=9,Parameters!$B$14+(Parameters!$B$15-Parameters!$B$14)*POWER((A7-5)/4,2),Parameters!$B$16)) | F7: =IF(A7<Parameters!$B$6,Parameters!$B$18*POWER(Parameters!$B$19,A7-1),0)
A8: 4 | B8: =Parameters!$B$42 | C8: =Parameters!$B$5*POWER(Parameters!$B$7,A8-1)/IF(Parameters!$B$7=1,Parameters!$B$6,(POWER(Parameters!$B$7,Parameters!$B$6)-1)/(Parameters!$B$7-1)) | D8: =SUM(C$5:C8) | E8: =IF(A8<=5,Parameters!$B$13+(Parameters!$B$14-Parameters!$B$13)*POWER((A8-1)/4,2),IF(A8<=9,Parameters!$B$14+(Parameters!$B$15-Parameters!$B$14)*POWER((A8-5)/4,2),Parameters!$B$16)) | F8: =IF(A8<Parameters!$B$6,Parameters!$B$18*POWER(Parameters!$B$19,A8-1),0)
A9: 5 | B9: =Parameters!$B$43 | C9: =Parameters!$B$5*POWER(Parameters!$B$7,A9-1)/IF(Parameters!$B$7=1,Parameters!$B$6,(POWER(Parameters!$B$7,Parameters!$B$6)-1)/(Parameters!$B$7-1)) | D9: =SUM(C$5:C9) | E9: =IF(A9<=5,Parameters!$B$13+(Parameters!$B$14-Parameters!$B$13)*POWER((A9-1)/4,2),IF(A9<=9,Parameters!$B$14+(Parameters!$B$15-Parameters!$B$14)*POWER((A9-5)/4,2),Parameters!$B$16)) | F9: =IF(A9<Parameters!$B$6,Parameters!$B$18*POWER(Parameters!$B$19,A9-1),0) | G9: PEAK.
A10: 6 | B10: =Parameters!$B$44 | C10: =Parameters!$B$5*POWER(Parameters!$B$7,A10-1)/IF(Parameters!$B$7=1,Parameters!$B$6,(POWER(Parameters!$B$7,Parameters!$B$6)-1)/(Parameters!$B$7-1)) | D10: =SUM(C$5:C10) | E10: =IF(A10<=5,Parameters!$B$13+(Parameters!$B$14-Parameters!$B$13)*POWER((A10-1)/4,2),IF(A10<=9,Parameters!$B$14+(Parameters!$B$15-Parameters!$B$14)*POWER((A10-5)/4,2),Parameters!$B$16)) | F10: =IF(A10<Parameters!$B$6,Parameters!$B$18*POWER(Parameters!$B$19,A10-1),0)
A11: 7 | B11: =Parameters!$B$45 | C11: =Parameters!$B$5*POWER(Parameters!$B$7,A11-1)/IF(Parameters!$B$7=1,Parameters!$B$6,(POWER(Parameters!$B$7,Parameters!$B$6)-1)/(Parameters!$B$7-1)) | D11: =SUM(C$5:C11) | E11: =IF(A11<=5,Parameters!$B$13+(Parameters!$B$14-Parameters!$B$13)*POWER((A11-1)/4,2),IF(A11<=9,Parameters!$B$14+(Parameters!$B$15-Parameters!$B$14)*POWER((A11-5)/4,2),Parameters!$B$16)) | F11: =IF(A11<Parameters!$B$6,Parameters!$B$18*POWER(Parameters!$B$19,A11-1),0)
A12: 8 | B12: =Parameters!$B$46 | C12: =Parameters!$B$5*POWER(Parameters!$B$7,A12-1)/IF(Parameters!$B$7=1,Parameters!$B$6,(POWER(Parameters!$B$7,Parameters!$B$6)-1)/(Parameters!$B$7-1)) | D12: =SUM(C$5:C12) | E12: =IF(A12<=5,Parameters!$B$13+(Parameters!$B$14-Parameters!$B$13)*POWER((A12-1)/4,2),IF(A12<=9,Parameters!$B$14+(Parameters!$B$15-Parameters!$B$14)*POWER((A12-5)/4,2),Parameters!$B$16)) | F12: =IF(A12<Parameters!$B$6,Parameters!$B$18*POWER(Parameters!$B$19,A12-1),0)
A13: 9 | B13: =Parameters!$B$47 | C13: =Parameters!$B$5*POWER(Parameters!$B$7,A13-1)/IF(Parameters!$B$7=1,Parameters!$B$6,(POWER(Parameters!$B$7,Parameters!$B$6)-1)/(Parameters!$B$7-1)) | D13: =SUM(C$5:C13) | E13: =IF(A13<=5,Parameters!$B$13+(Parameters!$B$14-Parameters!$B$13)*POWER((A13-1)/4,2),IF(A13<=9,Parameters!$B$14+(Parameters!$B$15-Parameters!$B$14)*POWER((A13-5)/4,2),Parameters!$B$16)) | F13: =IF(A13<Parameters!$B$6,Parameters!$B$18*POWER(Parameters!$B$19,A13-1),0)
A14: 10 | B14: =Parameters!$B$48 | C14: =Parameters!$B$5*POWER(Parameters!$B$7,A14-1)/IF(Parameters!$B$7=1,Parameters!$B$6,(POWER(Parameters!$B$7,Parameters!$B$6)-1)/(Parameters!$B$7-1)) | D14: =SUM(C$5:C14) | E14: =IF(A14<=5,Parameters!$B$13+(Parameters!$B$14-Parameters!$B$13)*POWER((A14-1)/4,2),IF(A14<=9,Parameters!$B$14+(Parameters!$B$15-Parameters!$B$14)*POWER((A14-5)/4,2),Parameters!$B$16)) | F14: =IF(A14<Parameters!$B$6,Parameters!$B$18*POWER(Parameters!$B$19,A14-1),0) | G14: Endgame.
A15: TOTAL | C15: =SUM(C5:C14) | F15: =SUM(F5:F14)

Sheet UpgradeSim
A1: UpgradeSim — Tier 1 (Solar System)
A2: 10-second tick simulation. Game ticks every 1 second under the hood; sim runs the COMPLETION path. See row 3 for headline timing metrics.
A3: Earliest possible transition (cohesion ready): | E3: =IFERROR(INDEX(B:B,MATCH(1,AO:AO,0))&" min","—") | H3: Actual transition (completion path): | M3: =IFERROR(INDEX(B:B,MATCH("transition",U:U,0))&" min","—")
A4: Tick | B4: Time (min) | C4: Mass start | D4: Cohesion | E4: SW | F4: AB | G4: SC | H4: Mag | I4: OR | J4: HP | K4: FP | L4: T2? | M4: MPC | N4: MPS | O4: APS | P4: Click inc | Q4: Auto inc | R4: Pass inc | S4: Total inc | T4: Mass post-inc | U4: Buy? | V4: Cost | W4: Coh + | X4: Mass end | Y4: M/sec | Z4: Note | AA4: SW M/min | AB4: AB M/min | AC4: SC M/min | AD4: Mag M/min | AE4: FP M/min | AF4: Base M/min | AG4: SW cost | AH4: AB cost | AI4: SC cost | AJ4: Mag cost | AK4: OR cost | AL4: HP cost | AM4: FP cost | AN4: Trans? | AO4: Could-trans? | AP4: Next OS cost | AQ4: Cheapest stack | AR4: Save mode | AS4: SW VPC | AT4: AB VPC | AU4: SC VPC | AV4: Mag VPC | AW4: Next OS VPC | AX4: Action
A5: 0 | B5: 0 | C5: 0 | D5: 0 | E5: 0 | F5: 0 | G5: 0 | H5: 0 | I5: 0 | J5: 0 | K5: 0 | L5: 0 | M5: =(Parameters!$B$9+(IF(E5=0,0,(Upgrades!$J$6+E5*Upgrades!$K$6)*POWER(Upgrades!$L$6,E5)))*(IF(Upgrades!$T$7="Solar Wind",POWER(Upgrades!$U$7,F5),1)*IF(Upgrades!$T$8="Solar Wind",POWER(Upgrades!$U$8,G5),1)*IF(Upgrades!$T$9="Solar Wind",POWER(Upgrades!$U$9,H5),1)*IF(Upgrades!$T$10="Solar Wind",POWER(Upgrades!$U$10,I5),1)*IF(Upgrades!$T$11="Solar Wind",POWER(Upgrades!$U$11,J5),1)*IF(Upgrades!$T$12="Solar Wind",POWER(Upgrades!$U$12,K5),1))+(IF(F5=0,0,(Upgrades!$J$7+F5*Upgrades!$K$7)*POWER(Upgrades!$L$7,F5)))*(IF(Upgrades!$T$6="Asteroid Belt",POWER(Upgrades!$U$6,E5),1)*IF(Upgrades!$T$8="Asteroid Belt",POWER(Upgrades!$U$8,G5),1)*IF(Upgrades!$T$9="Asteroid Belt",POWER(Upgrades!$U$9,H5),1)*IF(Upgrades!$T$10="Asteroid Belt",POWER(Upgrades!$U$10,I5),1)*IF(Upgrades!$T$11="Asteroid Belt",POWER(Upgrades!$U$11,J5),1)*IF(Upgrades!$T$12="Asteroid Belt",POWER(Upgrades!$U$12,K5),1))+(IF(G5=0,0,(Upgrades!$J$8+G5*Upgrades!$K$8)*POWER(Upgrades!$L$8,G5)))*(IF(Upgrades!$T$6="Stellar Coupling",POWER(Upgrades!$U$6,E5),1)*IF(Upgrades!$T$7="Stellar Coupling",POWER(Upgrades!$U$7,F5),1)*IF(Upgrades!$T$9="Stellar Coupling",POWER(Upgrades!$U$9,H5),1)*IF(Upgrades!$T$10="Stellar Coupling",POWER(Upgrades!$U$10,I5),1)*IF(Upgrades!$T$11="Stellar Coupling",POWER(Upgrades!$U$11,J5),1)*IF(Upgrades!$T$12="Stellar Coupling",POWER(Upgrades!$U$12,K5),1))+(IF(H5=0,0,(Upgrades!$J$9+H5*Upgrades!$K$9)*POWER(Upgrades!$L$9,H5)))*(IF(Upgrades!$T$6="Magnetosphere",POWER(Upgrades!$U$6,E5),1)*IF(Upgrades!$T$7="Magnetosphere",POWER(Upgrades!$U$7,F5),1)*IF(Upgrades!$T$8="Magnetosphere",POWER(Upgrades!$U$8,G5),1)*IF(Upgrades!$T$10="Magnetosphere",POWER(Upgrades!$U$10,I5),1)*IF(Upgrades!$T$11="Magnetosphere",POWER(Upgrades!$U$11,J5),1)*IF(Upgrades!$T$12="Magnetosphere",POWER(Upgrades!$U$12,K5),1))+(IF(I5=0,0,(Upgrades!$J$10+I5*Upgrades!$K$10)*POWER(Upgrades!$L$10,I5)))*(IF(Upgrades!$T$6="Orbital Resonance",POWER(Upgrades!$U$6,E5),1)*IF(Upgrades!$T$7="Orbital Resonance",POWER(Upgrades!$U$7,F5),1)*IF(Upgrades!$T$8="Orbital Resonance",POWER(Upgrades!$U$8,G5),1)*IF(Upgrades!$T$9="Orbital Resonance",POWER(Upgrades!$U$9,H5),1)*IF(Upgrades!$T$11="Orbital Resonance",POWER(Upgrades!$U$11,J5),1)*IF(Upgrades!$T$12="Orbital Resonance",POWER(Upgrades!$U$12,K5),1))+(IF(J5=0,0,(Upgrades!$J$11+J5*Upgrades!$K$11)*POWER(Upgrades!$L$11,J5)))*(IF(Upgrades!$T$6="Heliopause",POWER(Upgrades!$U$6,E5),1)*IF(Upgrades!$T$7="Heliopause",POWER(Upgrades!$U$7,F5),1)*IF(Upgrades!$T$8="Heliopause",POWER(Upgrades!$U$8,G5),1)*IF(Upgrades!$T$9="Heliopause",POWER(Upgrades!$U$9,H5),1)*IF(Upgrades!$T$10="Heliopause",POWER(Upgrades!$U$10,I5),1)*IF(Upgrades!$T$12="Heliopause",POWER(Upgrades!$U$12,K5),1))+(IF(K5=0,0,(Upgrades!$J$12+K5*Upgrades!$K$12)*POWER(Upgrades!$L$12,K5)))*(IF(Upgrades!$T$6="First Photons",POWER(Upgrades!$U$6,E5),1)*IF(Upgrades!$T$7="First Photons",POWER(Upgrades!$U$7,F5),1)*IF(Upgrades!$T$8="First Photons",POWER(Upgrades!$U$8,G5),1)*IF(Upgrades!$T$9="First Photons",POWER(Upgrades!$U$9,H5),1)*IF(Upgrades!$T$10="First Photons",POWER(Upgrades!$U$10,I5),1)*IF(Upgrades!$T$11="First Photons",POWER(Upgrades!$U$11,J5),1)))*POWER(Upgrades!$Q$6,E5)*POWER(Upgrades!$Q$7,F5)*POWER(Upgrades!$Q$8,G5)*POWER(Upgrades!$Q$9,H5)*POWER(Upgrades!$Q$10,I5)*POWER(Upgrades!$Q$11,J5)*POWER(Upgrades!$Q$12,K5) | N5: =((IF(E5=0,0,(Upgrades!$G$6+E5*Upgrades!$H$6)*POWER(Upgrades!$I$6,E5)))*(IF(Upgrades!$T$7="Solar Wind",POWER(Upgrades!$U$7,F5),1)*IF(Upgrades!$T$8="Solar Wind",POWER(Upgrades!$U$8,G5),1)*IF(Upgrades!$T$9="Solar Wind",POWER(Upgrades!$U$9,H5),1)*IF(Upgrades!$T$10="Solar Wind",POWER(Upgrades!$U$10,I5),1)*IF(Upgrades!$T$11="Solar Wind",POWER(Upgrades!$U$11,J5),1)*IF(Upgrades!$T$12="Solar Wind",POWER(Upgrades!$U$12,K5),1))+(IF(F5=0,0,(Upgrades!$G$7+F5*Upgrades!$H$7)*POWER(Upgrades!$I$7,F5)))*(IF(Upgrades!$T$6="Asteroid Belt",POWER(Upgrades!$U$6,E5),1)*IF(Upgrades!$T$8="Asteroid Belt",POWER(Upgrades!$U$8,G5),1)*IF(Upgrades!$T$9="Asteroid Belt",POWER(Upgrades!$U$9,H5),1)*IF(Upgrades!$T$10="Asteroid Belt",POWER(Upgrades!$U$10,I5),1)*IF(Upgrades!$T$11="Asteroid Belt",POWER(Upgrades!$U$11,J5),1)*IF(Upgrades!$T$12="Asteroid Belt",POWER(Upgrades!$U$12,K5),1))+(IF(G5=0,0,(Upgrades!$G$8+G5*Upgrades!$H$8)*POWER(Upgrades!$I$8,G5)))*(IF(Upgrades!$T$6="Stellar Coupling",POWER(Upgrades!$U$6,E5),1)*IF(Upgrades!$T$7="Stellar Coupling",POWER(Upgrades!$U$7,F5),1)*IF(Upgrades!$T$9="Stellar Coupling",POWER(Upgrades!$U$9,H5),1)*IF(Upgrades!$T$10="Stellar Coupling",POWER(Upgrades!$U$10,I5),1)*IF(Upgrades!$T$11="Stellar Coupling",POWER(Upgrades!$U$11,J5),1)*IF(Upgrades!$T$12="Stellar Coupling",POWER(Upgrades!$U$12,K5),1))+(IF(H5=0,0,(Upgrades!$G$9+H5*Upgrades!$H$9)*POWER(Upgrades!$I$9,H5)))*(IF(Upgrades!$T$6="Magnetosphere",POWER(Upgrades!$U$6,E5),1)*IF(Upgrades!$T$7="Magnetosphere",POWER(Upgrades!$U$7,F5),1)*IF(Upgrades!$T$8="Magnetosphere",POWER(Upgrades!$U$8,G5),1)*IF(Upgrades!$T$10="Magnetosphere",POWER(Upgrades!$U$10,I5),1)*IF(Upgrades!$T$11="Magnetosphere",POWER(Upgrades!$U$11,J5),1)*IF(Upgrades!$T$12="Magnetosphere",POWER(Upgrades!$U$12,K5),1))+(IF(I5=0,0,(Upgrades!$G$10+I5*Upgrades!$H$10)*POWER(Upgrades!$I$10,I5)))*(IF(Upgrades!$T$6="Orbital Resonance",POWER(Upgrades!$U$6,E5),1)*IF(Upgrades!$T$7="Orbital Resonance",POWER(Upgrades!$U$7,F5),1)*IF(Upgrades!$T$8="Orbital Resonance",POWER(Upgrades!$U$8,G5),1)*IF(Upgrades!$T$9="Orbital Resonance",POWER(Upgrades!$U$9,H5),1)*IF(Upgrades!$T$11="Orbital Resonance",POWER(Upgrades!$U$11,J5),1)*IF(Upgrades!$T$12="Orbital Resonance",POWER(Upgrades!$U$12,K5),1))+(IF(J5=0,0,(Upgrades!$G$11+J5*Upgrades!$H$11)*POWER(Upgrades!$I$11,J5)))*(IF(Upgrades!$T$6="Heliopause",POWER(Upgrades!$U$6,E5),1)*IF(Upgrades!$T$7="Heliopause",POWER(Upgrades!$U$7,F5),1)*IF(Upgrades!$T$8="Heliopause",POWER(Upgrades!$U$8,G5),1)*IF(Upgrades!$T$9="Heliopause",POWER(Upgrades!$U$9,H5),1)*IF(Upgrades!$T$10="Heliopause",POWER(Upgrades!$U$10,I5),1)*IF(Upgrades!$T$12="Heliopause",POWER(Upgrades!$U$12,K5),1))+(IF(K5=0,0,(Upgrades!$G$12+K5*Upgrades!$H$12)*POWER(Upgrades!$I$12,K5)))*(IF(Upgrades!$T$6="First Photons",POWER(Upgrades!$U$6,E5),1)*IF(Upgrades!$T$7="First Photons",POWER(Upgrades!$U$7,F5),1)*IF(Upgrades!$T$8="First Photons",POWER(Upgrades!$U$8,G5),1)*IF(Upgrades!$T$9="First Photons",POWER(Upgrades!$U$9,H5),1)*IF(Upgrades!$T$10="First Photons",POWER(Upgrades!$U$10,I5),1)*IF(Upgrades!$T$11="First Photons",POWER(Upgrades!$U$11,J5),1)))*POWER(Upgrades!$P$6,E5)*POWER(Upgrades!$P$7,F5)*POWER(Upgrades!$P$8,G5)*POWER(Upgrades!$P$9,H5)*POWER(Upgrades!$P$10,I5)*POWER(Upgrades!$P$11,J5)*POWER(Upgrades!$P$12,K5) | O5: =((IF(E5=0,0,(Upgrades!$M$6+E5*Upgrades!$N$6)*POWER(Upgrades!$O$6,E5)))*(IF(Upgrades!$T$7="Solar Wind",POWER(Upgrades!$U$7,F5),1)*IF(Upgrades!$T$8="Solar Wind",POWER(Upgrades!$U$8,G5),1)*IF(Upgrades!$T$9="Solar Wind",POWER(Upgrades!$U$9,H5),1)*IF(Upgrades!$T$10="Solar Wind",POWER(Upgrades!$U$10,I5),1)*IF(Upgrades!$T$11="Solar Wind",POWER(Upgrades!$U$11,J5),1)*IF(Upgrades!$T$12="Solar Wind",POWER(Upgrades!$U$12,K5),1))+(IF(F5=0,0,(Upgrades!$M$7+F5*Upgrades!$N$7)*POWER(Upgrades!$O$7,F5)))*(IF(Upgrades!$T$6="Asteroid Belt",POWER(Upgrades!$U$6,E5),1)*IF(Upgrades!$T$8="Asteroid Belt",POWER(Upgrades!$U$8,G5),1)*IF(Upgrades!$T$9="Asteroid Belt",POWER(Upgrades!$U$9,H5),1)*IF(Upgrades!$T$10="Asteroid Belt",POWER(Upgrades!$U$10,I5),1)*IF(Upgrades!$T$11="Asteroid Belt",POWER(Upgrades!$U$11,J5),1)*IF(Upgrades!$T$12="Asteroid Belt",POWER(Upgrades!$U$12,K5),1))+(IF(G5=0,0,(Upgrades!$M$8+G5*Upgrades!$N$8)*POWER(Upgrades!$O$8,G5)))*(IF(Upgrades!$T$6="Stellar Coupling",POWER(Upgrades!$U$6,E5),1)*IF(Upgrades!$T$7="Stellar Coupling",POWER(Upgrades!$U$7,F5),1)*IF(Upgrades!$T$9="Stellar Coupling",POWER(Upgrades!$U$9,H5),1)*IF(Upgrades!$T$10="Stellar Coupling",POWER(Upgrades!$U$10,I5),1)*IF(Upgrades!$T$11="Stellar Coupling",POWER(Upgrades!$U$11,J5),1)*IF(Upgrades!$T$12="Stellar Coupling",POWER(Upgrades!$U$12,K5),1))+(IF(H5=0,0,(Upgrades!$M$9+H5*Upgrades!$N$9)*POWER(Upgrades!$O$9,H5)))*(IF(Upgrades!$T$6="Magnetosphere",POWER(Upgrades!$U$6,E5),1)*IF(Upgrades!$T$7="Magnetosphere",POWER(Upgrades!$U$7,F5),1)*IF(Upgrades!$T$8="Magnetosphere",POWER(Upgrades!$U$8,G5),1)*IF(Upgrades!$T$10="Magnetosphere",POWER(Upgrades!$U$10,I5),1)*IF(Upgrades!$T$11="Magnetosphere",POWER(Upgrades!$U$11,J5),1)*IF(Upgrades!$T$12="Magnetosphere",POWER(Upgrades!$U$12,K5),1))+(IF(I5=0,0,(Upgrades!$M$10+I5*Upgrades!$N$10)*POWER(Upgrades!$O$10,I5)))*(IF(Upgrades!$T$6="Orbital Resonance",POWER(Upgrades!$U$6,E5),1)*IF(Upgrades!$T$7="Orbital Resonance",POWER(Upgrades!$U$7,F5),1)*IF(Upgrades!$T$8="Orbital Resonance",POWER(Upgrades!$U$8,G5),1)*IF(Upgrades!$T$9="Orbital Resonance",POWER(Upgrades!$U$9,H5),1)*IF(Upgrades!$T$11="Orbital Resonance",POWER(Upgrades!$U$11,J5),1)*IF(Upgrades!$T$12="Orbital Resonance",POWER(Upgrades!$U$12,K5),1))+(IF(J5=0,0,(Upgrades!$M$11+J5*Upgrades!$N$11)*POWER(Upgrades!$O$11,J5)))*(IF(Upgrades!$T$6="Heliopause",POWER(Upgrades!$U$6,E5),1)*IF(Upgrades!$T$7="Heliopause",POWER(Upgrades!$U$7,F5),1)*IF(Upgrades!$T$8="Heliopause",POWER(Upgrades!$U$8,G5),1)*IF(Upgrades!$T$9="Heliopause",POWER(Upgrades!$U$9,H5),1)*IF(Upgrades!$T$10="Heliopause",POWER(Upgrades!$U$10,I5),1)*IF(Upgrades!$T$12="Heliopause",POWER(Upgrades!$U$12,K5),1))+(IF(K5=0,0,(Upgrades!$M$12+K5*Upgrades!$N$12)*POWER(Upgrades!$O$12,K5)))*(IF(Upgrades!$T$6="First Photons",POWER(Upgrades!$U$6,E5),1)*IF(Upgrades!$T$7="First Photons",POWER(Upgrades!$U$7,F5),1)*IF(Upgrades!$T$8="First Photons",POWER(Upgrades!$U$8,G5),1)*IF(Upgrades!$T$9="First Photons",POWER(Upgrades!$U$9,H5),1)*IF(Upgrades!$T$10="First Photons",POWER(Upgrades!$U$10,I5),1)*IF(Upgrades!$T$11="First Photons",POWER(Upgrades!$U$11,J5),1)))*POWER(Upgrades!$R$6,E5)*POWER(Upgrades!$R$7,F5)*POWER(Upgrades!$R$8,G5)*POWER(Upgrades!$R$9,H5)*POWER(Upgrades!$R$10,I5)*POWER(Upgrades!$R$11,J5)*POWER(Upgrades!$R$12,K5) | P5: 0 | Q5: 0 | R5: 0 | S5: 0 | T5: 0 | V5: 0 | W5: 0 | X5: 0 | Y5: =M5*Parameters!$B$10/60*Parameters!$B$11+O5*M5+N5 | Z5: game start | AA5: =(IF(E5=0,0,(Upgrades!$G$6+E5*Upgrades!$H$6)*POWER(Upgrades!$I$6,E5)))*(IF(Upgrades!$T$7="Solar Wind",POWER(Upgrades!$U$7,F5),1)*IF(Upgrades!$T$8="Solar Wind",POWER(Upgrades!$U$8,G5),1)*IF(Upgrades!$T$9="Solar Wind",POWER(Upgrades!$U$9,H5),1)*IF(Upgrades!$T$10="Solar Wind",POWER(Upgrades!$U$10,I5),1)*IF(Upgrades!$T$11="Solar Wind",POWER(Upgrades!$U$11,J5),1)*IF(Upgrades!$T$12="Solar Wind",POWER(Upgrades!$U$12,K5),1))*POWER(Upgrades!$P$6,E5)*POWER(Upgrades!$P$7,F5)*POWER(Upgrades!$P$8,G5)*POWER(Upgrades!$P$9,H5)*POWER(Upgrades!$P$10,I5)*POWER(Upgrades!$P$11,J5)*POWER(Upgrades!$P$12,K5)*60 | AB5: =(IF(F5=0,0,(Upgrades!$G$7+F5*Upgrades!$H$7)*POWER(Upgrades!$I$7,F5)))*(IF(Upgrades!$T$6="Asteroid Belt",POWER(Upgrades!$U$6,E5),1)*IF(Upgrades!$T$8="Asteroid Belt",POWER(Upgrades!$U$8,G5),1)*IF(Upgrades!$T$9="Asteroid Belt",POWER(Upgrades!$U$9,H5),1)*IF(Upgrades!$T$10="Asteroid Belt",POWER(Upgrades!$U$10,I5),1)*IF(Upgrades!$T$11="Asteroid Belt",POWER(Upgrades!$U$11,J5),1)*IF(Upgrades!$T$12="Asteroid Belt",POWER(Upgrades!$U$12,K5),1))*POWER(Upgrades!$P$6,E5)*POWER(Upgrades!$P$7,F5)*POWER(Upgrades!$P$8,G5)*POWER(Upgrades!$P$9,H5)*POWER(Upgrades!$P$10,I5)*POWER(Upgrades!$P$11,J5)*POWER(Upgrades!$P$12,K5)*60 | AC5: =(IF(G5=0,0,(Upgrades!$J$8+G5*Upgrades!$K$8)*POWER(Upgrades!$L$8,G5)))*(IF(Upgrades!$T$6="Stellar Coupling",POWER(Upgrades!$U$6,E5),1)*IF(Upgrades!$T$7="Stellar Coupling",POWER(Upgrades!$U$7,F5),1)*IF(Upgrades!$T$9="Stellar Coupling",POWER(Upgrades!$U$9,H5),1)*IF(Upgrades!$T$10="Stellar Coupling",POWER(Upgrades!$U$10,I5),1)*IF(Upgrades!$T$11="Stellar Coupling",POWER(Upgrades!$U$11,J5),1)*IF(Upgrades!$T$12="Stellar Coupling",POWER(Upgrades!$U$12,K5),1))*POWER(Upgrades!$Q$6,E5)*POWER(Upgrades!$Q$7,F5)*POWER(Upgrades!$Q$8,G5)*POWER(Upgrades!$Q$9,H5)*POWER(Upgrades!$Q$10,I5)*POWER(Upgrades!$Q$11,J5)*POWER(Upgrades!$Q$12,K5)*Parameters!$B$10*Parameters!$B$11 | AD5: =(IF(H5=0,0,(Upgrades!$G$9+H5*Upgrades!$H$9)*POWER(Upgrades!$I$9,H5)))*(IF(Upgrades!$T$6="Magnetosphere",POWER(Upgrades!$U$6,E5),1)*IF(Upgrades!$T$7="Magnetosphere",POWER(Upgrades!$U$7,F5),1)*IF(Upgrades!$T$8="Magnetosphere",POWER(Upgrades!$U$8,G5),1)*IF(Upgrades!$T$10="Magnetosphere",POWER(Upgrades!$U$10,I5),1)*IF(Upgrades!$T$11="Magnetosphere",POWER(Upgrades!$U$11,J5),1)*IF(Upgrades!$T$12="Magnetosphere",POWER(Upgrades!$U$12,K5),1))*POWER(Upgrades!$P$6,E5)*POWER(Upgrades!$P$7,F5)*POWER(Upgrades!$P$8,G5)*POWER(Upgrades!$P$9,H5)*POWER(Upgrades!$P$10,I5)*POWER(Upgrades!$P$11,J5)*POWER(Upgrades!$P$12,K5)*60 | AE5: =(IF(K5=0,0,(Upgrades!$G$12+K5*Upgrades!$H$12)*POWER(Upgrades!$I$12,K5)))*(IF(Upgrades!$T$6="First Photons",POWER(Upgrades!$U$6,E5),1)*IF(Upgrades!$T$7="First Photons",POWER(Upgrades!$U$7,F5),1)*IF(Upgrades!$T$8="First Photons",POWER(Upgrades!$U$8,G5),1)*IF(Upgrades!$T$9="First Photons",POWER(Upgrades!$U$9,H5),1)*IF(Upgrades!$T$10="First Photons",POWER(Upgrades!$U$10,I5),1)*IF(Upgrades!$T$11="First Photons",POWER(Upgrades!$U$11,J5),1))*POWER(Upgrades!$P$6,E5)*POWER(Upgrades!$P$7,F5)*POWER(Upgrades!$P$8,G5)*POWER(Upgrades!$P$9,H5)*POWER(Upgrades!$P$10,I5)*POWER(Upgrades!$P$11,J5)*POWER(Upgrades!$P$12,K5)*60 | AF5: =Parameters!$B$9*POWER(Upgrades!$Q$6,E5)*POWER(Upgrades!$Q$7,F5)*POWER(Upgrades!$Q$8,G5)*POWER(Upgrades!$Q$9,H5)*POWER(Upgrades!$Q$10,I5)*POWER(Upgrades!$Q$11,J5)*POWER(Upgrades!$Q$12,K5)*(Parameters!$B$10*Parameters!$B$11+O5*60) | AG5: =IF(E5>=Upgrades!$E$6,"",Upgrades!$C$6*POWER(Upgrades!$D$6,E5)) | AH5: =IF(F5>=Upgrades!$E$7,"",Upgrades!$C$7*POWER(Upgrades!$D$7,F5)) | AI5: =IF(G5>=Upgrades!$E$8,"",Upgrades!$C$8*POWER(Upgrades!$D$8,G5)) | AJ5: =IF(H5>=Upgrades!$E$9,"",Upgrades!$C$9*POWER(Upgrades!$D$9,H5)) | AK5: =IF(I5>=Upgrades!$E$10,"",Upgrades!$C$10*POWER(Upgrades!$D$10,I5)) | AL5: =IF(J5>=Upgrades!$E$11,"",Upgrades!$C$11*POWER(Upgrades!$D$11,J5)) | AM5: =IF(K5>=Upgrades!$E$12,"",Upgrades!$C$12*POWER(Upgrades!$D$12,K5)) | AN5: =IF(AND(D5>=Parameters!$B$18,(H5>=Upgrades!$E$9)*(K5>=Upgrades!$E$12)=1,L5=0),1,"") | AO5: =IF(AND(D5>=Parameters!$B$18,L5=0),1,"") | AP5: =MIN(IF(ISNUMBER(AK5),AK5,9E15),IF(ISNUMBER(AL5),AL5,9E15),IF(ISNUMBER(AM5),AM5,9E15)) | AQ5: =MIN(IF(ISNUMBER(AG5),AG5,9E15),IF(ISNUMBER(AH5),AH5,9E15),IF(ISNUMBER(AI5),AI5,9E15),IF(ISNUMBER(AJ5),AJ5,9E15)) | AR5: =FALSE | AS5: 0 | AT5: 0 | AU5: 0 | AV5: 0 | AW5: 0
A6: 1 | B6: =A6*10/60 | C6: =X5 | D6: =D5+W5 | E6: =E5+IF(U5="SW",1,0) | F6: =F5+IF(U5="AB",1,0) | G6: =G5+IF(U5="SC",1,0) | H6: =H5+IF(U5="Mag",1,0) | I6: =MAX(I5,IF(U5="OR",1,0)) | J6: =MAX(J5,IF(U5="HP",1,0)) | K6: =MAX(K5,IF(U5="FP",1,0)) | L6: =MAX(L5,IF(U5="transition",1,0)) | M6: =(Parameters!$B$9+(IF(E6=0,0,(Upgrades!$J$6+E6*Upgrades!$K$6)*POWER(Upgrades!$L$6,E6)))*(IF(Upgrades!$T$7="Solar Wind",POWER(Upgrades!$U$7,F6),1)*IF(Upgrades!$T$8="Solar Wind",POWER(Upgrades!$U$8,G6),1)*IF(Upgrades!$T$9="Solar Wind",POWER(Upgrades!$U$9,H6),1)*IF(Upgrades!$T$10="Solar Wind",POWER(Upgrades!$U$10,I6),1)*IF(Upgrades!$T$11="Solar Wind",POWER(Upgrades!$U$11,J6),1)*IF(Upgrades!$T$12="Solar Wind",POWER(Upgrades!$U$12,K6),1))+(IF(F6=0,0,(Upgrades!$J$7+F6*Upgrades!$K$7)*POWER(Upgrades!$L$7,F6)))*(IF(Upgrades!$T$6="Asteroid Belt",POWER(Upgrades!$U$6,E6),1)*IF(Upgrades!$T$8="Asteroid Belt",POWER(Upgrades!$U$8,G6),1)*IF(Upgrades!$T$9="Asteroid Belt",POWER(Upgrades!$U$9,H6),1)*IF(Upgrades!$T$10="Asteroid Belt",POWER(Upgrades!$U$10,I6),1)*IF(Upgrades!$T$11="Asteroid Belt",POWER(Upgrades!$U$11,J6),1)*IF(Upgrades!$T$12="Asteroid Belt",POWER(Upgrades!$U$12,K6),1))+(IF(G6=0,0,(Upgrades!$J$8+G6*Upgrades!$K$8)*POWER(Upgrades!$L$8,G6)))*(IF(Upgrades!$T$6="Stellar Coupling",POWER(Upgrades!$U$6,E6),1)*IF(Upgrades!$T$7="Stellar Coupling",POWER(Upgrades!$U$7,F6),1)*IF(Upgrades!$T$9="Stellar Coupling",POWER(Upgrades!$U$9,H6),1)*IF(Upgrades!$T$10="Stellar Coupling",POWER(Upgrades!$U$10,I6),1)*IF(Upgrades!$T$11="Stellar Coupling",POWER(Upgrades!$U$11,J6),1)*IF(Upgrades!$T$12="Stellar Coupling",POWER(Upgrades!$U$12,K6),1))+(IF(H6=0,0,(Upgrades!$J$9+H6*Upgrades!$K$9)*POWER(Upgrades!$L$9,H6)))*(IF(Upgrades!$T$6="Magnetosphere",POWER(Upgrades!$U$6,E6),1)*IF(Upgrades!$T$7="Magnetosphere",POWER(Upgrades!$U$7,F6),1)*IF(Upgrades!$T$8="Magnetosphere",POWER(Upgrades!$U$8,G6),1)*IF(Upgrades!$T$10="Magnetosphere",POWER(Upgrades!$U$10,I6),1)*IF(Upgrades!$T$11="Magnetosphere",POWER(Upgrades!$U$11,J6),1)*IF(Upgrades!$T$12="Magnetosphere",POWER(Upgrades!$U$12,K6),1))+(IF(I6=0,0,(Upgrades!$J$10+I6*Upgrades!$K$10)*POWER(Upgrades!$L$10,I6)))*(IF(Upgrades!$T$6="Orbital Resonance",POWER(Upgrades!$U$6,E6),1)*IF(Upgrades!$T$7="Orbital Resonance",POWER(Upgrades!$U$7,F6),1)*IF(Upgrades!$T$8="Orbital Resonance",POWER(Upgrades!$U$8,G6),1)*IF(Upgrades!$T$9="Orbital Resonance",POWER(Upgrades!$U$9,H6),1)*IF(Upgrades!$T$11="Orbital Resonance",POWER(Upgrades!$U$11,J6),1)*IF(Upgrades!$T$12="Orbital Resonance",POWER(Upgrades!$U$12,K6),1))+(IF(J6=0,0,(Upgrades!$J$11+J6*Upgrades!$K$11)*POWER(Upgrades!$L$11,J6)))*(IF(Upgrades!$T$6="Heliopause",POWER(Upgrades!$U$6,E6),1)*IF(Upgrades!$T$7="Heliopause",POWER(Upgrades!$U$7,F6),1)*IF(Upgrades!$T$8="Heliopause",POWER(Upgrades!$U$8,G6),1)*IF(Upgrades!$T$9="Heliopause",POWER(Upgrades!$U$9,H6),1)*IF(Upgrades!$T$10="Heliopause",POWER(Upgrades!$U$10,I6),1)*IF(Upgrades!$T$12="Heliopause",POWER(Upgrades!$U$12,K6),1))+(IF(K6=0,0,(Upgrades!$J$12+K6*Upgrades!$K$12)*POWER(Upgrades!$L$12,K6)))*(IF(Upgrades!$T$6="First Photons",POWER(Upgrades!$U$6,E6),1)*IF(Upgrades!$T$7="First Photons",POWER(Upgrades!$U$7,F6),1)*IF(Upgrades!$T$8="First Photons",POWER(Upgrades!$U$8,G6),1)*IF(Upgrades!$T$9="First Photons",POWER(Upgrades!$U$9,H6),1)*IF(Upgrades!$T$10="First Photons",POWER(Upgrades!$U$10,I6),1)*IF(Upgrades!$T$11="First Photons",POWER(Upgrades!$U$11,J6),1)))*POWER(Upgrades!$Q$6,E6)*POWER(Upgrades!$Q$7,F6)*POWER(Upgrades!$Q$8,G6)*POWER(Upgrades!$Q$9,H6)*POWER(Upgrades!$Q$10,I6)*POWER(Upgrades!$Q$11,J6)*POWER(Upgrades!$Q$12,K6) | N6: =((IF(E6=0,0,(Upgrades!$G$6+E6*Upgrades!$H$6)*POWER(Upgrades!$I$6,E6)))*(IF(Upgrades!$T$7="Solar Wind",POWER(Upgrades!$U$7,F6),1)*IF(Upgrades!$T$8="Solar Wind",POWER(Upgrades!$U$8,G6),1)*IF(Upgrades!$T$9="Solar Wind",POWER(Upgrades!$U$9,H6),1)*IF(Upgrades!$T$10="Solar Wind",POWER(Upgrades!$U$10,I6),1)*IF(Upgrades!$T$11="Solar Wind",POWER(Upgrades!$U$11,J6),1)*IF(Upgrades!$T$12="Solar Wind",POWER(Upgrades!$U$12,K6),1))+(IF(F6=0,0,(Upgrades!$G$7+F6*Upgrades!$H$7)*POWER(Upgrades!$I$7,F6)))*(IF(Upgrades!$T$6="Asteroid Belt",POWER(Upgrades!$U$6,E6),1)*IF(Upgrades!$T$8="Asteroid Belt",POWER(Upgrades!$U$8,G6),1)*IF(Upgrades!$T$9="Asteroid Belt",POWER(Upgrades!$U$9,H6),1)*IF(Upgrades!$T$10="Asteroid Belt",POWER(Upgrades!$U$10,I6),1)*IF(Upgrades!$T$11="Asteroid Belt",POWER(Upgrades!$U$11,J6),1)*IF(Upgrades!$T$12="Asteroid Belt",POWER(Upgrades!$U$12,K6),1))+(IF(G6=0,0,(Upgrades!$G$8+G6*Upgrades!$H$8)*POWER(Upgrades!$I$8,G6)))*(IF(Upgrades!$T$6="Stellar Coupling",POWER(Upgrades!$U$6,E6),1)*IF(Upgrades!$T$7="Stellar Coupling",POWER(Upgrades!$U$7,F6),1)*IF(Upgrades!$T$9="Stellar Coupling",POWER(Upgrades!$U$9,H6),1)*IF(Upgrades!$T$10="Stellar Coupling",POWER(Upgrades!$U$10,I6),1)*IF(Upgrades!$T$11="Stellar Coupling",POWER(Upgrades!$U$11,J6),1)*IF(Upgrades!$T$12="Stellar Coupling",POWER(Upgrades!$U$12,K6),1))+(IF(H6=0,0,(Upgrades!$G$9+H6*Upgrades!$H$9)*POWER(Upgrades!$I$9,H6)))*(IF(Upgrades!$T$6="Magnetosphere",POWER(Upgrades!$U$6,E6),1)*IF(Upgrades!$T$7="Magnetosphere",POWER(Upgrades!$U$7,F6),1)*IF(Upgrades!$T$8="Magnetosphere",POWER(Upgrades!$U$8,G6),1)*IF(Upgrades!$T$10="Magnetosphere",POWER(Upgrades!$U$10,I6),1)*IF(Upgrades!$T$11="Magnetosphere",POWER(Upgrades!$U$11,J6),1)*IF(Upgrades!$T$12="Magnetosphere",POWER(Upgrades!$U$12,K6),1))+(IF(I6=0,0,(Upgrades!$G$10+I6*Upgrades!$H$10)*POWER(Upgrades!$I$10,I6)))*(IF(Upgrades!$T$6="Orbital Resonance",POWER(Upgrades!$U$6,E6),1)*IF(Upgrades!$T$7="Orbital Resonance",POWER(Upgrades!$U$7,F6),1)*IF(Upgrades!$T$8="Orbital Resonance",POWER(Upgrades!$U$8,G6),1)*IF(Upgrades!$T$9="Orbital Resonance",POWER(Upgrades!$U$9,H6),1)*IF(Upgrades!$T$11="Orbital Resonance",POWER(Upgrades!$U$11,J6),1)*IF(Upgrades!$T$12="Orbital Resonance",POWER(Upgrades!$U$12,K6),1))+(IF(J6=0,0,(Upgrades!$G$11+J6*Upgrades!$H$11)*POWER(Upgrades!$I$11,J6)))*(IF(Upgrades!$T$6="Heliopause",POWER(Upgrades!$U$6,E6),1)*IF(Upgrades!$T$7="Heliopause",POWER(Upgrades!$U$7,F6),1)*IF(Upgrades!$T$8="Heliopause",POWER(Upgrades!$U$8,G6),1)*IF(Upgrades!$T$9="Heliopause",POWER(Upgrades!$U$9,H6),1)*IF(Upgrades!$T$10="Heliopause",POWER(Upgrades!$U$10,I6),1)*IF(Upgrades!$T$12="Heliopause",POWER(Upgrades!$U$12,K6),1))+(IF(K6=0,0,(Upgrades!$G$12+K6*Upgrades!$H$12)*POWER(Upgrades!$I$12,K6)))*(IF(Upgrades!$T$6="First Photons",POWER(Upgrades!$U$6,E6),1)*IF(Upgrades!$T$7="First Photons",POWER(Upgrades!$U$7,F6),1)*IF(Upgrades!$T$8="First Photons",POWER(Upgrades!$U$8,G6),1)*IF(Upgrades!$T$9="First Photons",POWER(Upgrades!$U$9,H6),1)*IF(Upgrades!$T$10="First Photons",POWER(Upgrades!$U$10,I6),1)*IF(Upgrades!$T$11="First Photons",POWER(Upgrades!$U$11,J6),1)))*POWER(Upgrades!$P$6,E6)*POWER(Upgrades!$P$7,F6)*POWER(Upgrades!$P$8,G6)*POWER(Upgrades!$P$9,H6)*POWER(Upgrades!$P$10,I6)*POWER(Upgrades!$P$11,J6)*POWER(Upgrades!$P$12,K6) | O6: =((IF(E6=0,0,(Upgrades!$M$6+E6*Upgrades!$N$6)*POWER(Upgrades!$O$6,E6)))*(IF(Upgrades!$T$7="Solar Wind",POWER(Upgrades!$U$7,F6),1)*IF(Upgrades!$T$8="Solar Wind",POWER(Upgrades!$U$8,G6),1)*IF(Upgrades!$T$9="Solar Wind",POWER(Upgrades!$U$9,H6),1)*IF(Upgrades!$T$10="Solar Wind",POWER(Upgrades!$U$10,I6),1)*IF(Upgrades!$T$11="Solar Wind",POWER(Upgrades!$U$11,J6),1)*IF(Upgrades!$T$12="Solar Wind",POWER(Upgrades!$U$12,K6),1))+(IF(F6=0,0,(Upgrades!$M$7+F6*Upgrades!$N$7)*POWER(Upgrades!$O$7,F6)))*(IF(Upgrades!$T$6="Asteroid Belt",POWER(Upgrades!$U$6,E6),1)*IF(Upgrades!$T$8="Asteroid Belt",POWER(Upgrades!$U$8,G6),1)*IF(Upgrades!$T$9="Asteroid Belt",POWER(Upgrades!$U$9,H6),1)*IF(Upgrades!$T$10="Asteroid Belt",POWER(Upgrades!$U$10,I6),1)*IF(Upgrades!$T$11="Asteroid Belt",POWER(Upgrades!$U$11,J6),1)*IF(Upgrades!$T$12="Asteroid Belt",POWER(Upgrades!$U$12,K6),1))+(IF(G6=0,0,(Upgrades!$M$8+G6*Upgrades!$N$8)*POWER(Upgrades!$O$8,G6)))*(IF(Upgrades!$T$6="Stellar Coupling",POWER(Upgrades!$U$6,E6),1)*IF(Upgrades!$T$7="Stellar Coupling",POWER(Upgrades!$U$7,F6),1)*IF(Upgrades!$T$9="Stellar Coupling",POWER(Upgrades!$U$9,H6),1)*IF(Upgrades!$T$10="Stellar Coupling",POWER(Upgrades!$U$10,I6),1)*IF(Upgrades!$T$11="Stellar Coupling",POWER(Upgrades!$U$11,J6),1)*IF(Upgrades!$T$12="Stellar Coupling",POWER(Upgrades!$U$12,K6),1))+(IF(H6=0,0,(Upgrades!$M$9+H6*Upgrades!$N$9)*POWER(Upgrades!$O$9,H6)))*(IF(Upgrades!$T$6="Magnetosphere",POWER(Upgrades!$U$6,E6),1)*IF(Upgrades!$T$7="Magnetosphere",POWER(Upgrades!$U$7,F6),1)*IF(Upgrades!$T$8="Magnetosphere",POWER(Upgrades!$U$8,G6),1)*IF(Upgrades!$T$10="Magnetosphere",POWER(Upgrades!$U$10,I6),1)*IF(Upgrades!$T$11="Magnetosphere",POWER(Upgrades!$U$11,J6),1)*IF(Upgrades!$T$12="Magnetosphere",POWER(Upgrades!$U$12,K6),1))+(IF(I6=0,0,(Upgrades!$M$10+I6*Upgrades!$N$10)*POWER(Upgrades!$O$10,I6)))*(IF(Upgrades!$T$6="Orbital Resonance",POWER(Upgrades!$U$6,E6),1)*IF(Upgrades!$T$7="Orbital Resonance",POWER(Upgrades!$U$7,F6),1)*IF(Upgrades!$T$8="Orbital Resonance",POWER(Upgrades!$U$8,G6),1)*IF(Upgrades!$T$9="Orbital Resonance",POWER(Upgrades!$U$9,H6),1)*IF(Upgrades!$T$11="Orbital Resonance",POWER(Upgrades!$U$11,J6),1)*IF(Upgrades!$T$12="Orbital Resonance",POWER(Upgrades!$U$12,K6),1))+(IF(J6=0,0,(Upgrades!$M$11+J6*Upgrades!$N$11)*POWER(Upgrades!$O$11,J6)))*(IF(Upgrades!$T$6="Heliopause",POWER(Upgrades!$U$6,E6),1)*IF(Upgrades!$T$7="Heliopause",POWER(Upgrades!$U$7,F6),1)*IF(Upgrades!$T$8="Heliopause",POWER(Upgrades!$U$8,G6),1)*IF(Upgrades!$T$9="Heliopause",POWER(Upgrades!$U$9,H6),1)*IF(Upgrades!$T$10="Heliopause",POWER(Upgrades!$U$10,I6),1)*IF(Upgrades!$T$12="Heliopause",POWER(Upgrades!$U$12,K6),1))+(IF(K6=0,0,(Upgrades!$M$12+K6*Upgrades!$N$12)*POWER(Upgrades!$O$12,K6)))*(IF(Upgrades!$T$6="First Photons",POWER(Upgrades!$U$6,E6),1)*IF(Upgrades!$T$7="First Photons",POWER(Upgrades!$U$7,F6),1)*IF(Upgrades!$T$8="First Photons",POWER(Upgrades!$U$8,G6),1)*IF(Upgrades!$T$9="First Photons",POWER(Upgrades!$U$9,H6),1)*IF(Upgrades!$T$10="First Photons",POWER(Upgrades!$U$10,I6),1)*IF(Upgrades!$T$11="First Photons",POWER(Upgrades!$U$11,J6),1)))*POWER(Upgrades!$R$6,E6)*POWER(Upgrades!$R$7,F6)*POWER(Upgrades!$R$8,G6)*POWER(Upgrades!$R$9,H6)*POWER(Upgrades!$R$10,I6)*POWER(Upgrades!$R$11,J6)*POWER(Upgrades!$R$12,K6) | P6: =IF(L6=1,0,M6*Parameters!$B$10/60*Parameters!$B$11*10) | Q6: =IF(L6=1,0,O6*M6*10) | R6: =IF(L6=1,0,N6*10) | S6: =P6+Q6+R6 | T6: =C6+S6 | U6: =AX6 | V6: =IF(U6="",0,IF(U6="transition",0,IF(U6="SW",AG6,IF(U6="AB",AH6,IF(U6="SC",AI6,IF(U6="Mag",AJ6,IF(U6="OR",AK6,IF(U6="HP",AL6,IF(U6="FP",AM6,0))))))))) | W6: =IF(U6="OR",Upgrades!$F$10,IF(U6="HP",Upgrades!$F$11,IF(U6="transition",-Parameters!$B$18,0))) | X6: =T6-V6 | Y6: =M6*Parameters!$B$10/60*Parameters!$B$11+O6*M6+N6 | Z6: =IF(U6="transition","→ Tier 2 (Stellar Neighborhood)",IF(U6="FP","First Photons — light begins, system quickens",IF(U6="HP","Heliopause acquired",IF(U6="OR","Orbital Resonance — passive multiplier active",IF(AND(AO6=1,L6=0,AN6<>1),"Cohesion ready (waiting on completionist upgrades)",""))))) | AA6: =(IF(E6=0,0,(Upgrades!$G$6+E6*Upgrades!$H$6)*POWER(Upgrades!$I$6,E6)))*(IF(Upgrades!$T$7="Solar Wind",POWER(Upgrades!$U$7,F6),1)*IF(Upgrades!$T$8="Solar Wind",POWER(Upgrades!$U$8,G6),1)*IF(Upgrades!$T$9="Solar Wind",POWER(Upgrades!$U$9,H6),1)*IF(Upgrades!$T$10="Solar Wind",POWER(Upgrades!$U$10,I6),1)*IF(Upgrades!$T$11="Solar Wind",POWER(Upgrades!$U$11,J6),1)*IF(Upgrades!$T$12="Solar Wind",POWER(Upgrades!$U$12,K6),1))*POWER(Upgrades!$P$6,E6)*POWER(Upgrades!$P$7,F6)*POWER(Upgrades!$P$8,G6)*POWER(Upgrades!$P$9,H6)*POWER(Upgrades!$P$10,I6)*POWER(Upgrades!$P$11,J6)*POWER(Upgrades!$P$12,K6)*60 | AB6: =(IF(F6=0,0,(Upgrades!$G$7+F6*Upgrades!$H$7)*POWER(Upgrades!$I$7,F6)))*(IF(Upgrades!$T$6="Asteroid Belt",POWER(Upgrades!$U$6,E6),1)*IF(Upgrades!$T$8="Asteroid Belt",POWER(Upgrades!$U$8,G6),1)*IF(Upgrades!$T$9="Asteroid Belt",POWER(Upgrades!$U$9,H6),1)*IF(Upgrades!$T$10="Asteroid Belt",POWER(Upgrades!$U$10,I6),1)*IF(Upgrades!$T$11="Asteroid Belt",POWER(Upgrades!$U$11,J6),1)*IF(Upgrades!$T$12="Asteroid Belt",POWER(Upgrades!$U$12,K6),1))*POWER(Upgrades!$P$6,E6)*POWER(Upgrades!$P$7,F6)*POWER(Upgrades!$P$8,G6)*POWER(Upgrades!$P$9,H6)*POWER(Upgrades!$P$10,I6)*POWER(Upgrades!$P$11,J6)*POWER(Upgrades!$P$12,K6)*60 | AC6: =(IF(G6=0,0,(Upgrades!$J$8+G6*Upgrades!$K$8)*POWER(Upgrades!$L$8,G6)))*(IF(Upgrades!$T$6="Stellar Coupling",POWER(Upgrades!$U$6,E6),1)*IF(Upgrades!$T$7="Stellar Coupling",POWER(Upgrades!$U$7,F6),1)*IF(Upgrades!$T$9="Stellar Coupling",POWER(Upgrades!$U$9,H6),1)*IF(Upgrades!$T$10="Stellar Coupling",POWER(Upgrades!$U$10,I6),1)*IF(Upgrades!$T$11="Stellar Coupling",POWER(Upgrades!$U$11,J6),1)*IF(Upgrades!$T$12="Stellar Coupling",POWER(Upgrades!$U$12,K6),1))*POWER(Upgrades!$Q$6,E6)*POWER(Upgrades!$Q$7,F6)*POWER(Upgrades!$Q$8,G6)*POWER(Upgrades!$Q$9,H6)*POWER(Upgrades!$Q$10,I6)*POWER(Upgrades!$Q$11,J6)*POWER(Upgrades!$Q$12,K6)*Parameters!$B$10*Parameters!$B$11 | AD6: =(IF(H6=0,0,(Upgrades!$G$9+H6*Upgrades!$H$9)*POWER(Upgrades!$I$9,H6)))*(IF(Upgrades!$T$6="Magnetosphere",POWER(Upgrades!$U$6,E6),1)*IF(Upgrades!$T$7="Magnetosphere",POWER(Upgrades!$U$7,F6),1)*IF(Upgrades!$T$8="Magnetosphere",POWER(Upgrades!$U$8,G6),1)*IF(Upgrades!$T$10="Magnetosphere",POWER(Upgrades!$U$10,I6),1)*IF(Upgrades!$T$11="Magnetosphere",POWER(Upgrades!$U$11,J6),1)*IF(Upgrades!$T$12="Magnetosphere",POWER(Upgrades!$U$12,K6),1))*POWER(Upgrades!$P$6,E6)*POWER(Upgrades!$P$7,F6)*POWER(Upgrades!$P$8,G6)*POWER(Upgrades!$P$9,H6)*POWER(Upgrades!$P$10,I6)*POWER(Upgrades!$P$11,J6)*POWER(Upgrades!$P$12,K6)*60 | AE6: =(IF(K6=0,0,(Upgrades!$G$12+K6*Upgrades!$H$12)*POWER(Upgrades!$I$12,K6)))*(IF(Upgrades!$T$6="First Photons",POWER(Upgrades!$U$6,E6),1)*IF(Upgrades!$T$7="First Photons",POWER(Upgrades!$U$7,F6),1)*IF(Upgrades!$T$8="First Photons",POWER(Upgrades!$U$8,G6),1)*IF(Upgrades!$T$9="First Photons",POWER(Upgrades!$U$9,H6),1)*IF(Upgrades!$T$10="First Photons",POWER(Upgrades!$U$10,I6),1)*IF(Upgrades!$T$11="First Photons",POWER(Upgrades!$U$11,J6),1))*POWER(Upgrades!$P$6,E6)*POWER(Upgrades!$P$7,F6)*POWER(Upgrades!$P$8,G6)*POWER(Upgrades!$P$9,H6)*POWER(Upgrades!$P$10,I6)*POWER(Upgrades!$P$11,J6)*POWER(Upgrades!$P$12,K6)*60 | AF6: =Parameters!$B$9*POWER(Upgrades!$Q$6,E6)*POWER(Upgrades!$Q$7,F6)*POWER(Upgrades!$Q$8,G6)*POWER(Upgrades!$Q$9,H6)*POWER(Upgrades!$Q$10,I6)*POWER(Upgrades!$Q$11,J6)*POWER(Upgrades!$Q$12,K6)*(Parameters!$B$10*Parameters!$B$11+O6*60) | AG6: =IF(E6>=Upgrades!$E$6,"",Upgrades!$C$6*POWER(Upgrades!$D$6,E6)) | AH6: =IF(F6>=Upgrades!$E$7,"",Upgrades!$C$7*POWER(Upgrades!$D$7,F6)) | AI6: =IF(G6>=Upgrades!$E$8,"",Upgrades!$C$8*POWER(Upgrades!$D$8,G6)) | AJ6: =IF(H6>=Upgrades!$E$9,"",Upgrades!$C$9*POWER(Upgrades!$D$9,H6)) | AK6: =IF(I6>=Upgrades!$E$10,"",Upgrades!$C$10*POWER(Upgrades!$D$10,I6)) | AL6: =IF(J6>=Upgrades!$E$11,"",Upgrades!$C$11*POWER(Upgrades!$D$11,J6)) | AM6: =IF(K6>=Upgrades!$E$12,"",Upgrades!$C$12*POWER(Upgrades!$D$12,K6)) | AN6: =IF(AND(D6>=Parameters!$B$18,(H6>=Upgrades!$E$9)*(K6>=Upgrades!$E$12)=1,L6=0),1,"") | AO6: =IF(AND(D6>=Parameters!$B$18,L6=0),1,"") | AP6: =MIN(IF(ISNUMBER(AK6),AK6,9E15),IF(ISNUMBER(AL6),AL6,9E15),IF(ISNUMBER(AM6),AM6,9E15)) | AQ6: =MIN(IF(ISNUMBER(AG6),AG6,9E15),IF(ISNUMBER(AH6),AH6,9E15),IF(ISNUMBER(AI6),AI6,9E15),IF(ISNUMBER(AJ6),AJ6,9E15)) | AR6: =IF(AW6>Parameters!$B$21*(MAX(IF(AND(NOT(AND(AO6=1,AN6<>1)),ISNUMBER(AG6),AG6<=T6),AS6,0),IF(AND(NOT(AND(AO6=1,AN6<>1)),ISNUMBER(AH6),AH6<=T6),AT6,0),IF(AND(NOT(AND(AO6=1,AN6<>1)),ISNUMBER(AI6),AI6<=T6),AU6,0),IF(AND(ISNUMBER(AJ6),AJ6<=T6),AV6,0))),TRUE,FALSE) | AS6: =IFERROR(Upgrades!$H$6*(POWER(Upgrades!$P$6,E6)*POWER(Upgrades!$P$7,F6)*POWER(Upgrades!$P$8,G6)*POWER(Upgrades!$P$9,H6)*POWER(Upgrades!$P$10,I6)*POWER(Upgrades!$P$11,J6)*POWER(Upgrades!$P$12,K6))*(IF(Upgrades!$T$7="Solar Wind",POWER(Upgrades!$U$7,F6),1)*IF(Upgrades!$T$8="Solar Wind",POWER(Upgrades!$U$8,G6),1)*IF(Upgrades!$T$9="Solar Wind",POWER(Upgrades!$U$9,H6),1)*IF(Upgrades!$T$10="Solar Wind",POWER(Upgrades!$U$10,I6),1)*IF(Upgrades!$T$11="Solar Wind",POWER(Upgrades!$U$11,J6),1)*IF(Upgrades!$T$12="Solar Wind",POWER(Upgrades!$U$12,K6),1))/AG6,0) | AT6: =IFERROR(Upgrades!$H$7*(POWER(Upgrades!$P$6,E6)*POWER(Upgrades!$P$7,F6)*POWER(Upgrades!$P$8,G6)*POWER(Upgrades!$P$9,H6)*POWER(Upgrades!$P$10,I6)*POWER(Upgrades!$P$11,J6)*POWER(Upgrades!$P$12,K6))*(IF(Upgrades!$T$6="Asteroid Belt",POWER(Upgrades!$U$6,E6),1)*IF(Upgrades!$T$8="Asteroid Belt",POWER(Upgrades!$U$8,G6),1)*IF(Upgrades!$T$9="Asteroid Belt",POWER(Upgrades!$U$9,H6),1)*IF(Upgrades!$T$10="Asteroid Belt",POWER(Upgrades!$U$10,I6),1)*IF(Upgrades!$T$11="Asteroid Belt",POWER(Upgrades!$U$11,J6),1)*IF(Upgrades!$T$12="Asteroid Belt",POWER(Upgrades!$U$12,K6),1))/AH6,0) | AU6: =IFERROR(Upgrades!$K$8*(POWER(Upgrades!$Q$6,E6)*POWER(Upgrades!$Q$7,F6)*POWER(Upgrades!$Q$8,G6)*POWER(Upgrades!$Q$9,H6)*POWER(Upgrades!$Q$10,I6)*POWER(Upgrades!$Q$11,J6)*POWER(Upgrades!$Q$12,K6))*(IF(Upgrades!$T$6="Stellar Coupling",POWER(Upgrades!$U$6,E6),1)*IF(Upgrades!$T$7="Stellar Coupling",POWER(Upgrades!$U$7,F6),1)*IF(Upgrades!$T$9="Stellar Coupling",POWER(Upgrades!$U$9,H6),1)*IF(Upgrades!$T$10="Stellar Coupling",POWER(Upgrades!$U$10,I6),1)*IF(Upgrades!$T$11="Stellar Coupling",POWER(Upgrades!$U$11,J6),1)*IF(Upgrades!$T$12="Stellar Coupling",POWER(Upgrades!$U$12,K6),1))*Parameters!$B$10*Parameters!$B$11/60/AI6,0) | AV6: =IFERROR(Upgrades!$H$9*(POWER(Upgrades!$P$6,E6)*POWER(Upgrades!$P$7,F6)*POWER(Upgrades!$P$8,G6)*POWER(Upgrades!$P$9,H6)*POWER(Upgrades!$P$10,I6)*POWER(Upgrades!$P$11,J6)*POWER(Upgrades!$P$12,K6))*(IF(Upgrades!$T$6="Magnetosphere",POWER(Upgrades!$U$6,E6),1)*IF(Upgrades!$T$7="Magnetosphere",POWER(Upgrades!$U$7,F6),1)*IF(Upgrades!$T$8="Magnetosphere",POWER(Upgrades!$U$8,G6),1)*IF(Upgrades!$T$10="Magnetosphere",POWER(Upgrades!$U$10,I6),1)*IF(Upgrades!$T$11="Magnetosphere",POWER(Upgrades!$U$11,J6),1)*IF(Upgrades!$T$12="Magnetosphere",POWER(Upgrades!$U$12,K6),1))/AJ6,0) | AW6: =MAX(IF(I6>0,0,IFERROR(0.25*N6/Upgrades!$C$10,0)),IF(J6>0,0,IFERROR(0.5*((IF(G6=0,0,(Upgrades!$J$8+G6*Upgrades!$K$8)*POWER(Upgrades!$L$8,G6)))*(IF(Upgrades!$T$6="Stellar Coupling",POWER(Upgrades!$U$6,E6),1)*IF(Upgrades!$T$7="Stellar Coupling",POWER(Upgrades!$U$7,F6),1)*IF(Upgrades!$T$9="Stellar Coupling",POWER(Upgrades!$U$9,H6),1)*IF(Upgrades!$T$10="Stellar Coupling",POWER(Upgrades!$U$10,I6),1)*IF(Upgrades!$T$11="Stellar Coupling",POWER(Upgrades!$U$11,J6),1)*IF(Upgrades!$T$12="Stellar Coupling",POWER(Upgrades!$U$12,K6),1))*(POWER(Upgrades!$Q$6,E6)*POWER(Upgrades!$Q$7,F6)*POWER(Upgrades!$Q$8,G6)*POWER(Upgrades!$Q$9,H6)*POWER(Upgrades!$Q$10,I6)*POWER(Upgrades!$Q$11,J6)*POWER(Upgrades!$Q$12,K6))*Parameters!$B$10*Parameters!$B$11/60)/Upgrades!$C$11,0)),IF(K6>0,0,IFERROR((1.0*(POWER(Upgrades!$P$6,E6)*POWER(Upgrades!$P$7,F6)*POWER(Upgrades!$P$8,G6)*POWER(Upgrades!$P$9,H6)*POWER(Upgrades!$P$10,I6)*POWER(Upgrades!$P$11,J6)*POWER(Upgrades!$P$12,K6))+0.20*M6*Parameters!$B$10*Parameters!$B$11/60)/Upgrades!$C$12,0)),IF(AND(ISNUMBER(AG6),AG6>T6),AS6,0),IF(AND(ISNUMBER(AH6),AH6>T6),AT6,0),IF(AND(ISNUMBER(AI6),AI6>T6),AU6,0),IF(AND(ISNUMBER(AJ6),AJ6>T6),AV6,0)) | AX6: =IF(AN6=1,"transition",IF(MIN(IF(AND(I6=0,ISNUMBER(AK6),AK6<=T6),AK6,9E15),IF(AND(J6=0,ISNUMBER(AL6),AL6<=T6),AL6,9E15),IF(AND(K6=0,ISNUMBER(AM6),AM6<=T6),AM6,9E15))<9E15,IF(AND(AND(I6=0,ISNUMBER(AK6),AK6<=T6),AK6=MIN(IF(AND(I6=0,ISNUMBER(AK6),AK6<=T6),AK6,9E15),IF(AND(J6=0,ISNUMBER(AL6),AL6<=T6),AL6,9E15),IF(AND(K6=0,ISNUMBER(AM6),AM6<=T6),AM6,9E15))),"OR",IF(AND(AND(J6=0,ISNUMBER(AL6),AL6<=T6),AL6=MIN(IF(AND(I6=0,ISNUMBER(AK6),AK6<=T6),AK6,9E15),IF(AND(J6=0,ISNUMBER(AL6),AL6<=T6),AL6,9E15),IF(AND(K6=0,ISNUMBER(AM6),AM6<=T6),AM6,9E15))),"HP","FP")),IF(AR6=TRUE,"",IF(MAX(IF(AND(NOT(AND(AO6=1,AN6<>1)),ISNUMBER(AG6),AG6<=T6),AS6,0),IF(AND(NOT(AND(AO6=1,AN6<>1)),ISNUMBER(AH6),AH6<=T6),AT6,0),IF(AND(NOT(AND(AO6=1,AN6<>1)),ISNUMBER(AI6),AI6<=T6),AU6,0),IF(AND(ISNUMBER(AJ6),AJ6<=T6),AV6,0))<=0,"",IF(AND(IF(AND(NOT(AND(AO6=1,AN6<>1)),ISNUMBER(AG6),AG6<=T6),AS6,0)>0,IF(AND(NOT(AND(AO6=1,AN6<>1)),ISNUMBER(AG6),AG6<=T6),AS6,0)=MAX(IF(AND(NOT(AND(AO6=1,AN6<>1)),ISNUMBER(AG6),AG6<=T6),AS6,0),IF(AND(NOT(AND(AO6=1,AN6<>1)),ISNUMBER(AH6),AH6<=T6),AT6,0),IF(AND(NOT(AND(AO6=1,AN6<>1)),ISNUMBER(AI6),AI6<=T6),AU6,0),IF(AND(ISNUMBER(AJ6),AJ6<=T6),AV6,0))),"SW",IF(AND(IF(AND(NOT(AND(AO6=1,AN6<>1)),ISNUMBER(AH6),AH6<=T6),AT6,0)>0,IF(AND(NOT(AND(AO6=1,AN6<>1)),ISNUMBER(AH6),AH6<=T6),AT6,0)=MAX(IF(AND(NOT(AND(AO6=1,AN6<>1)),ISNUMBER(AG6),AG6<=T6),AS6,0),IF(AND(NOT(AND(AO6=1,AN6<>1)),ISNUMBER(AH6),AH6<=T6),AT6,0),IF(AND(NOT(AND(AO6=1,AN6<>1)),ISNUMBER(AI6),AI6<=T6),AU6,0),IF(AND(ISNUMBER(AJ6),AJ6<=T6),AV6,0))),"AB",IF(AND(IF(AND(NOT(AND(AO6=1,AN6<>1)),ISNUMBER(AI6),AI6<=T6),AU6,0)>0,IF(AND(NOT(AND(AO6=1,AN6<>1)),ISNUMBER(AI6),AI6<=T6),AU6,0)=MAX(IF(AND(NOT(AND(AO6=1,AN6<>1)),ISNUMBER(AG6),AG6<=T6),AS6,0),IF(AND(NOT(AND(AO6=1,AN6<>1)),ISNUMBER(AH6),AH6<=T6),AT6,0),IF(AND(NOT(AND(AO6=1,AN6<>1)),ISNUMBER(AI6),AI6<=T6),AU6,0),IF(AND(ISNUMBER(AJ6),AJ6<=T6),AV6,0))),"SC","Mag")))))))
